Workbook

Sheet __Instrukce
A1: Pro přidání nového projektu k zaměstnanci
A2: - zkopírujte CELÝ řádek jiného existujícího projektu
A3: - NEkopírujte řádek z excelu pro rok 2024!!
A4: - vyberte si ze seznamu jméno projektu (sl. B), ostatní parametry se dotáhnou přes vzorec - v ostatních sl. (A, C-H) nic ručně nepřepisujte!!
A5: - nepřepisujte a neupravujte žádné vzorce
A6: - nenechávejte prosím řádky se vzorci bez projektu
A8: Pro vytvoření projektu
A9: - pokud projekt neexistuje, je potřeba ho zadat na listu číselník - zásahy v číselníku provádí výhradně Daniela Doksanská nebo Jan Lukáš
A11: Při jakékoliv nefunkčnosti kontaktujte Danielu Doksanskou
A13: Pro přidání zaměstnance
A14: - kontaktujte Danielu Doksanskou
A16: Pro odstranění projektu u určitého kolegy
... A27: kapacity nutné v daném období

Sheet Bár
A1: =RIGHT(CELL("názevsouboru"),LEN(CELL("názevsouboru"))-FIND("]",CELL("názevsouboru"))) -> Faflík | B1: ANA | I1: =__Ciselnik!L2 -> 45292 | N1: =EDATE(I1,1) -> 45323 | R1: =EDATE(N1,1) -> 45352 | V1: =EDATE(R1,1) -> 45383 | AA1: =EDATE(V1,1) -> 45413 | AE1: =EDATE(AA1,1) -> 45444 | AI1: =EDATE(AE1,1) -> 45474 | AN1: =EDATE(AI1,1) -> 45505 | AR1: =EDATE(AN1,1) -> 45536 | AV1: =EDATE(AR1,1) -> 45566 | BA1: =EDATE(AV1,1) -> 45597 | BE1: =EDATE(BA1,1) -> 45627 | BL1: Plánované hodiny celkem
A2: Kurátor: | B2: Roman B. | G2: Týden | I2: 1 | J2: 2 | K2: 3 | L2: 4 | M2: 5 | N2: 6 | O2: 7 | P2: 8 | Q2: 9 | R2: 10 | S2: 11 | T2: 12 | U2: 13 | V2: 14 | W2: 15 | X2: 16 | Y2: 17 | Z2: 18 | AA2: 19 | AB2: 20 | AC2: 21 | AD2: 22 | AE2: 23 | AF2: 24 | AG2: 25 | AH2: 26 | AI2: 27 | AJ2: 28 | AK2: 29 | AL2: 30 | AM2: 31 | AN2: 32 | AO2: 33 | AP2: 34 | AQ2: 35 | AR2: 36 | AS2: 37 | AT2: 38 | AU2: 39 | AV2: 40 | AW2: 41 | AX2: 42 | AY2: 43 | AZ2: 44 | BA2: 45 | BB2: 46 | BC2: 47 | BD2: 48 | BE2: 49 | BF2: 50 | BG2: 51 | BH2: 52 | BI2: 53 | BL2: =__Ciselnik!L2 -> 45292 | BM2: =EDATE(BL2,1) -> 45323 | BN2: =EDATE(BM2,1) -> 45352 | BO2: =EDATE(BN2,1) -> 45383 | BP2: =EDATE(BO2,1) -> 45413 | BQ2: =EDATE(BP2,1) -> 45444 | BR2: =EDATE(BQ2,1) -> 45474 | BS2: =EDATE(BR2,1) -> 45505 | BT2: =EDATE(BS2,1) -> 45536 | ... BW2: =EDATE(BV2,1) -> 45627 | BX2: 2026
A3: Jednotka: | B3: telco | G3: Kapacita | I3: 8 | J3: 40 | K3: 40 | L3: 40 | M3: 40 | N3: 40 | O3: 40 | P3: 40 | Q3: 40 | R3: 40 | S3: 40 | T3: 40 | U3: 40 | V3: 32 | W3: 32 | X3: 40 | Y3: 40 | Z3: 32 | AA3: 32 | AB3: 40 | AC3: 40 | AD3: 40 | AE3: 40 | AF3: 40 | AG3: 40 | AH3: 40 | AI3: 40 | AJ3: 32 | AK3: 40 | AL3: 40 | AM3: 40 | AN3: 40 | AO3: 40 | AP3: 40 | AQ3: 40 | AR3: 40 | AS3: 40 | AT3: 40 | AU3: 40 | AV3: 32 | AW3: 40 | AX3: 40 | AY3: 40 | AZ3: 32 | BA3: 40 | BB3: 40 | BC3: 32 | BD3: 40 | BE3: 40 | BF3: 40 | BG3: 40 | BH3: 24 | BI3: 32 | BL3: =SUM(I3:M3) -> 168 | BM3: =SUM(N3:Q3) -> 160 | BN3: =SUM(R3:U3)+(2/4*V3) -> 176 | BO3: =SUM(W3:Z3)+(2/4*V3) -> 160 | BP3: =SUM(AA3:AD3) -> 152 | BQ3: =SUM(AE3:AH3)+(2/5*AI3) -> 176 | BR3: =SUM(AJ3:AM3)+(3/5*AI3) -> 176 | BS3: =SUM(AN3:AQ3)+(1/5*AR3) -> 168 | BT3: =SUM(AS3:AU3)+(4/5*AR3)+(2/4*AV3) -> 168 | BU3: =SUM(AW3:AZ3)+(2/4*AV3) -> 168 | BV3: =SUM(BA3:BD3)+(1/5*BE3) -> 160 | BW3: =SUM(BF3:BI3)+(4/5*BE3) -> 168 | BX3: =SUM(BL3:BW3) -> 2000
A4: Generovat | B4: Ano | G4: Volná kapacita | I4: =I3-I5 -> #N/A | J4: =J3-J5 -> #N/A | K4: =K3-K5 -> #N/A | L4: =L3-L5 -> #N/A | M4: =M3-M5 -> #N/A | N4: =N3-N5 -> #N/A | O4: =O3-O5 -> #N/A | P4: =P3-P5 -> #N/A | ... BI4: =BI3-BI5 -> #N/A | BL4: =BL3-BL5 -> 112 | BM4: =BM3-BM5 -> 60 | BN4: =BN3-BN5 -> #VALUE! | BO4: =BO3-BO5 -> #VALUE! | BP4: =BP3-BP5 -> 96 | BQ4: =BQ3-BQ5 -> #VALUE! | BR4: =BR3-BR5 -> #VALUE! | BS4: =BS3-BS5 -> #VALUE! | ... BW4: =BW3-BW5 -> #VALUE! | BX4: =SUM(BL4:BW4) -> #VALUE!
G5: Celkové vytížení | I5: =SUMPRODUCT(I10:I34,$H$10:$H$34) -> #N/A | J5: =SUMPRODUCT(J10:J34,$H$10:$H$34) -> #N/A | K5: =SUMPRODUCT(K10:K34,$H$10:$H$34) -> #N/A | L5: =SUMPRODUCT(L10:L34,$H$10:$H$34) -> #N/A | M5: =SUMPRODUCT(M10:M34,$H$10:$H$34) -> #N/A | N5: =SUMPRODUCT(N10:N34,$H$10:$H$34) -> #N/A | O5: =SUMPRODUCT(O10:O34,$H$10:$H$34) -> #N/A | P5: =SUMPRODUCT(P10:P34,$H$10:$H$34) -> #N/A | ... BI5: =SUMPRODUCT(BI10:BI34,$H$10:$H$34) -> #N/A | BL5: =SUM(BL10:BL34) -> 56 | BM5: =SUM(BM10:BM34) -> 100 | BN5: =SUM(BN10:BN34) -> #VALUE! | BO5: =SUM(BO10:BO34) -> #VALUE! | BP5: =SUM(BP10:BP34) -> 56 | BQ5: =SUM(BQ10:BQ34) -> #VALUE! | BR5: =SUM(BR10:BR34) -> #VALUE! | BS5: =SUM(BS10:BS34) -> #VALUE! | ... BX5: =SUM(BX10:BX34) -> #VALUE!
G6: V rámci SP97 | I6: {=SUMPRODUCT(I10:I34,$H$10:$H$34*($E$10:$E$34="USYC.SP97"))} -> #N/A | J6: {=SUMPRODUCT(J10:J34,$H$10:$H$34*($E$10:$E$34="USYC.SP97"))} -> #N/A | K6: {=SUMPRODUCT(K10:K34,$H$10:$H$34*($E$10:$E$34="USYC.SP97"))} -> #N/A | L6: {=SUMPRODUCT(L10:L34,$H$10:$H$34*($E$10:$E$34="USYC.SP97"))} -> #N/A | M6: {=SUMPRODUCT(M10:M34,$H$10:$H$34*($E$10:$E$34="USYC.SP97"))} -> #N/A | N6: {=SUMPRODUCT(N10:N34,$H$10:$H$34*($E$10:$E$34="USYC.SP97"))} -> #N/A | O6: {=SUMPRODUCT(O10:O34,$H$10:$H$34*($E$10:$E$34="USYC.SP97"))} -> #N/A | P6: {=SUMPRODUCT(P10:P34,$H$10:$H$34*($E$10:$E$34="USYC.SP97"))} -> #N/A | ... BI6: {=SUMPRODUCT(BI10:BI34,$H$10:$H$34*($E$10:$E$34="USYC.SP97"))} -> #N/A | BL6: =SUMIF($E$10:$E$34,"USYC.SP97",BL10:BL34) -> 0 | BM6: =SUMIF($E$10:$E$34,"USYC.SP97",BM10:BM34) -> 0 | BN6: =SUMIF($E$10:$E$34,"USYC.SP97",BN10:BN34) -> #VALUE! | BO6: =SUMIF($E$10:$E$34,"USYC.SP97",BO10:BO34) -> #VALUE! | BP6: =SUMIF($E$10:$E$34,"USYC.SP97",BP10:BP34) -> 8 | BQ6: =SUMIF($E$10:$E$34,"USYC.SP97",BQ10:BQ34) -> #VALUE! | BR6: =SUMIF($E$10:$E$34,"USYC.SP97",BR10:BR34) -> #VALUE! | BS6: =SUMIF($E$10:$E$34,"USYC.SP97",BS10:BS34) -> #VALUE! | ... BX6: =SUMIF($E$10:$E$34,"USYC.SP97",BX10:BX34) -> #VALUE!
G7: V rámci SP98 | I7: {=SUMPRODUCT(I10:I34,$H$10:$H$34*($E$10:$E$34="USYC.SP98"))} -> #N/A | J7: {=SUMPRODUCT(J10:J34,$H$10:$H$34*($E$10:$E$34="USYC.SP98"))} -> #N/A | K7: {=SUMPRODUCT(K10:K34,$H$10:$H$34*($E$10:$E$34="USYC.SP98"))} -> #N/A | L7: {=SUMPRODUCT(L10:L34,$H$10:$H$34*($E$10:$E$34="USYC.SP98"))} -> #N/A | M7: {=SUMPRODUCT(M10:M34,$H$10:$H$34*($E$10:$E$34="USYC.SP98"))} -> #N/A | N7: {=SUMPRODUCT(N10:N34,$H$10:$H$34*($E$10:$E$34="USYC.SP98"))} -> #N/A | O7: {=SUMPRODUCT(O10:O34,$H$10:$H$34*($E$10:$E$34="USYC.SP98"))} -> #N/A | P7: {=SUMPRODUCT(P10:P34,$H$10:$H$34*($E$10:$E$34="USYC.SP98"))} -> #N/A | ... BI7: {=SUMPRODUCT(BI10:BI34,$H$10:$H$34*($E$10:$E$34="USYC.SP98"))} -> #N/A | BL7: =SUMIF($E$10:$E$34,"USYC.SP98",BL10:BL34) -> 48 | BM7: =SUMIF($E$10:$E$34,"USYC.SP98",BM10:BM34) -> 20 | BN7: =SUMIF($E$10:$E$34,"USYC.SP98",BN10:BN34) -> 44 | BO7: =SUMIF($E$10:$E$34,"USYC.SP98",BO10:BO34) -> 36 | BP7: =SUMIF($E$10:$E$34,"USYC.SP98",BP10:BP34) -> 32 | BQ7: =SUMIF($E$10:$E$34,"USYC.SP98",BQ10:BQ34) -> 32 | BR7: =SUMIF($E$10:$E$34,"USYC.SP98",BR10:BR34) -> 4 | BS7: =SUMIF($E$10:$E$34,"USYC.SP98",BS10:BS34) -> 17 | ... BX7: =SUMIF($E$10:$E$34,"USYC.SP98",BX10:BX34) -> 308
G8: Externě | I8: {=SUMPRODUCT(I10:I34,$H$10:$H$34*($E$10:$E$34="Ext"))} -> #N/A | J8: {=SUMPRODUCT(J10:J34,$H$10:$H$34*($E$10:$E$34="Ext"))} -> #N/A | K8: {=SUMPRODUCT(K10:K34,$H$10:$H$34*($E$10:$E$34="Ext"))} -> #N/A | L8: {=SUMPRODUCT(L10:L34,$H$10:$H$34*($E$10:$E$34="Ext"))} -> #N/A | M8: {=SUMPRODUCT(M10:M34,$H$10:$H$34*($E$10:$E$34="Ext"))} -> #N/A | N8: {=SUMPRODUCT(N10:N34,$H$10:$H$34*($E$10:$E$34="Ext"))} -> #N/A | O8: {=SUMPRODUCT(O10:O34,$H$10:$H$34*($E$10:$E$34="Ext"))} -> #N/A | P8: {=SUMPRODUCT(P10:P34,$H$10:$H$34*($E$10:$E$34="Ext"))} -> #N/A | ... BI8: {=SUMPRODUCT(BI10:BI34,$H$10:$H$34*($E$10:$E$34="Ext"))} -> #N/A | BL8: =SUMIF($E$10:$E$34,"Ext",BL10:BL34) -> 8 | BM8: =SUMIF($E$10:$E$34,"Ext",BM10:BM34) -> 80 | BN8: =SUMIF($E$10:$E$34,"Ext",BN10:BN34) -> 0 | BO8: =SUMIF($E$10:$E$34,"Ext",BO10:BO34) -> 16 | BP8: =SUMIF($E$10:$E$34,"Ext",BP10:BP34) -> 16 | BQ8: =SUMIF($E$10:$E$34,"Ext",BQ10:BQ34) -> 16 | BR8: =SUMIF($E$10:$E$34,"Ext",BR10:BR34) -> 136 | BS8: =SUMIF($E$10:$E$34,"Ext",BS10:BS34) -> 0 | ... BX8: =SUMIF($E$10:$E$34,"Ext",BX10:BX34) -> 408
A9: Klient | B9: Projekt | C9: BC | D9: Deal Unit | E9: Jednotka | F9: Oblast | G9: PM | H9: Koef. | I9: - | J9: - | K9: - | L9: - | M9: - | N9: - | O9: - | P9: - | Q9: - | R9: - | S9: - | T9: - | U9: - | V9: - | W9: - | X9: - | Y9: - | Z9: - | AA9: - | AB9: - | AC9: - | AD9: - | AE9: - | AF9: - | AG9: - | AH9: - | AI9: - | AJ9: - | AK9: - | AL9: - | AM9: - | AN9: - | AO9: - | AP9: - | AQ9: - | AR9: - | AS9: - | AT9: - | AU9: - | AV9: - | AW9: - | AX9: - | AY9: - | AZ9: - | BA9: - | BB9: - | BC9: - | BD9: - | BE9: - | BF9: - | BG9: - | BH9: - | BI9: - | BJ9: Plán | BK9: Zbývá
A10: =VLOOKUP($B10,__Ciselnik!$A$1:$B$202,2,FALSE) -> - | B10: =__Ciselnik!A2 -> _aktivity mimo Geo | C10: =VLOOKUP($B10,__Ciselnik!$A$1:$H$202,7,FALSE) -> - | D10: =VLOOKUP($B10,__Ciselnik!$A$1:$H$202,8,FALSE) -> - | E10: =VLOOKUP($B10,__Ciselnik!$A$1:$I$202,9,FALSE) -> Ext | F10: =VLOOKUP($B10,__Ciselnik!$A$1:$C$202,3,FALSE) -> - | G10: =VLOOKUP($B10,__Ciselnik!$A$1:$D$202,4,FALSE) -> - | H10: =VLOOKUP($B10,__Ciselnik!$A$1:$E$202,5,FALSE) -> 1 | BK10: =BJ10-SUM(I10:BI10) -> 0 | BL10: =SUM(I10:M10) -> 0 | BM10: =SUM(N10:Q10) -> 0 | BN10: =SUM(R10:U10)+(2/4*V10) -> 0 | BO10: =SUM(W10:Z10)+(2/4*V10) -> 0 | BP10: =SUM(AA10:AD10) -> 0 | BQ10: =SUM(AE10:AH10)+(2/5*AI10) -> 0 | BR10: =SUM(AJ10:AM10)+(3/5*AI10) -> 0 | BS10: =SUM(AN10:AQ10)+(1/5*AR10) -> 0 | BT10: =SUM(AS10:AU10)+(4/5*AR10)+(2/4*AV10) -> 0 | BU10: =SUM(AW10:AZ10)+(2/4*AV10) -> 0 | BV10: =SUM(BA10:BD10)+(1/5*BE10) -> 0 | BW10: =SUM(BF10:BI10)+(4/5*BE10) -> 0 | BX10: =SUM(BL10:BW10) -> 0
A11: =VLOOKUP($B11,__Ciselnik!$A$1:$B$202,2,FALSE) -> - | B11: =__Ciselnik!A3 -> _dovolená/nemoc | C11: =VLOOKUP($B11,__Ciselnik!$A$1:$H$202,7,FALSE) -> - | D11: =VLOOKUP($B11,__Ciselnik!$A$1:$H$202,8,FALSE) -> - | E11: =VLOOKUP($B11,__Ciselnik!$A$1:$I$202,9,FALSE) -> Ext | F11: =VLOOKUP($B11,__Ciselnik!$A$1:$C$202,3,FALSE) -> - | G11: =VLOOKUP($B11,__Ciselnik!$A$1:$D$202,4,FALSE) -> - | H11: =VLOOKUP($B11,__Ciselnik!$A$1:$E$202,5,FALSE) -> 1 | I11: 8 | O11: 40 | P11: 40 | Z11: 16 | AA11: 16 | AI11: 40 | AJ11: 32 | AL11: 40 | AM11: 40 | AU11: 16 | AZ11: 16 | BB11: 40 | BC11: 8 | BH11: 24 | BI11: 32 | BJ11: 200 | BK11: =BJ11-SUM(I11:BI11) -> -208 | BL11: =SUM(I11:M11) -> 8 | BM11: =SUM(N11:Q11) -> 80 | BN11: =SUM(R11:U11)+(2/4*V11) -> 0 | BO11: =SUM(W11:Z11)+(2/4*V11) -> 16 | BP11: =SUM(AA11:AD11) -> 16 | BQ11: =SUM(AE11:AH11)+(2/5*AI11) -> 16 | BR11: =SUM(AJ11:AM11)+(3/5*AI11) -> 136 | BS11: =SUM(AN11:AQ11)+(1/5*AR11) -> 0 | BT11: =SUM(AS11:AU11)+(4/5*AR11)+(2/4*AV11) -> 16 | BU11: =SUM(AW11:AZ11)+(2/4*AV11) -> 16 | BV11: =SUM(BA11:BD11)+(1/5*BE11) -> 48 | BW11: =SUM(BF11:BI11)+(4/5*BE11) -> 56 | BX11: =SUM(BL11:BW11) -> 408
A12: =VLOOKUP($B12,__Ciselnik!$A$1:$B$202,2,FALSE) -> - | B12: _presale 97 | C12: =VLOOKUP($B12,__Ciselnik!$A$1:$H$202,7,FALSE) -> psc.sp97 | D12: =VLOOKUP($B12,__Ciselnik!$A$1:$H$202,8,FALSE) -> - | E12: =VLOOKUP($B12,__Ciselnik!$A$1:$I$202,9,FALSE) -> USYC.SP97 | F12: =VLOOKUP($B12,__Ciselnik!$A$1:$C$202,3,FALSE) -> - | G12: =VLOOKUP($B12,__Ciselnik!$A$1:$D$202,4,FALSE) -> - | H12: =VLOOKUP($B12,__Ciselnik!$A$1:$E$202,5,FALSE) -> 1 | BK12: =BJ12-SUM(I12:BI12) -> 0 | BL12: =SUM(I12:M12) -> 0 | BM12: =SUM(N12:Q12) -> 0 | BN12: =SUM(R12:U12)+(2/4*V12) -> 0 | BO12: =SUM(W12:Z12)+(2/4*V12) -> 0 | BP12: =SUM(AA12:AD12) -> 0 | BQ12: =SUM(AE12:AH12)+(2/5*AI12) -> 0 | BR12: =SUM(AJ12:AM12)+(3/5*AI12) -> 0 | BS12: =SUM(AN12:AQ12)+(1/5*AR12) -> 0 | BT12: =SUM(AS12:AU12)+(4/5*AR12)+(2/4*AV12) -> 0 | BU12: =SUM(AW12:AZ12)+(2/4*AV12) -> 0 | BV12: =SUM(BA12:BD12)+(1/5*BE12) -> 0 | BW12: =SUM(BF12:BI12)+(4/5*BE12) -> 0 | BX12: =SUM(BL12:BW12) -> 0
A13: =VLOOKUP($B13,__Ciselnik!$A$1:$B$202,2,FALSE) -> - | B13: =__Ciselnik!A7 -> _režie | C13: =VLOOKUP($B13,__Ciselnik!$A$1:$H$202,7,FALSE) -> - | D13: =VLOOKUP($B13,__Ciselnik!$A$1:$H$202,8,FALSE) -> - | E13: =VLOOKUP($B13,__Ciselnik!$A$1:$I$202,9,FALSE) -> Ext | F13: =VLOOKUP($B13,__Ciselnik!$A$1:$C$202,3,FALSE) -> - | G13: =VLOOKUP($B13,__Ciselnik!$A$1:$D$202,4,FALSE) -> - | H13: =VLOOKUP($B13,__Ciselnik!$A$1:$E$202,5,FALSE) -> 1 | BK13: =BJ13-SUM(I13:BI13) -> 0 | BL13: =SUM(I13:M13) -> 0 | BM13: =SUM(N13:Q13) -> 0 | BN13: =SUM(R13:U13)+(2/4*V13) -> 0 | BO13: =SUM(W13:Z13)+(2/4*V13) -> 0 | BP13: =SUM(AA13:AD13) -> 0 | BQ13: =SUM(AE13:AH13)+(2/5*AI13) -> 0 | BR13: =SUM(AJ13:AM13)+(3/5*AI13) -> 0 | BS13: =SUM(AN13:AQ13)+(1/5*AR13) -> 0 | BT13: =SUM(AS13:AU13)+(4/5*AR13)+(2/4*AV13) -> 0 | BU13: =SUM(AW13:AZ13)+(2/4*AV13) -> 0 | BV13: =SUM(BA13:BD13)+(1/5*BE13) -> 0 | BW13: =SUM(BF13:BI13)+(4/5*BE13) -> 0 | BX13: =SUM(BL13:BW13) -> 0
A14: =VLOOKUP($B14,__Ciselnik!$A$1:$B$202,2,FALSE) -> #N/A | B14: EAD97 vzdělávání | C14: =VLOOKUP($B14,__Ciselnik!$A$1:$H$202,7,FALSE) -> #N/A | D14: =VLOOKUP($B14,__Ciselnik!$A$1:$H$202,8,FALSE) -> #N/A | E14: =VLOOKUP($B14,__Ciselnik!$A$1:$I$202,9,FALSE) -> #N/A | F14: =VLOOKUP($B14,__Ciselnik!$A$1:$C$202,3,FALSE) -> #N/A | G14: =VLOOKUP($B14,__Ciselnik!$A$1:$D$202,4,FALSE) -> #N/A | H14: =VLOOKUP($B14,__Ciselnik!$A$1:$E$202,5,FALSE) -> #N/A | BJ14: 0 | BK14: =BJ14-SUM(I14:BI14) -> 0 | BL14: =SUM(I14:M14) -> 0 | BM14: =SUM(N14:Q14) -> 0 | BN14: =SUM(R14:U14)+(2/4*V14) -> 0 | BO14: =SUM(W14:Z14)+(2/4*V14) -> 0 | BP14: =SUM(AA14:AD14) -> 0 | BQ14: =SUM(AE14:AH14)+(2/5*AI14) -> 0 | BR14: =SUM(AJ14:AM14)+(3/5*AI14) -> 0 | BS14: =SUM(AN14:AQ14)+(1/5*AR14) -> 0 | BT14: =SUM(AS14:AU14)+(4/5*AR14)+(2/4*AV14) -> 0 | BU14: =SUM(AW14:AZ14)+(2/4*AV14) -> 0 | BV14: =SUM(BA14:BD14)+(1/5*BE14) -> 0 | BW14: =SUM(BF14:BI14)+(4/5*BE14) -> 0 | BX14: =SUM(BL14:BW14) -> 0
A15: =VLOOKUP($B15,__Ciselnik!$A$1:$B$202,2,FALSE) -> SŽ | B15: DTMZ | C15: =VLOOKUP($B15,__Ciselnik!$A$1:$H$202,7,FALSE) -> psc.sp98.dtmz-bc | D15: =VLOOKUP($B15,__Ciselnik!$A$1:$H$202,8,FALSE) -> psc.sp98.dtmz | E15: =VLOOKUP($B15,__Ciselnik!$A$1:$I$202,9,FALSE) -> USYC.SP98 | F15: =VLOOKUP($B15,__Ciselnik!$A$1:$C$202,3,FALSE) -> VEST | G15: =VLOOKUP($B15,__Ciselnik!$A$1:$D$202,4,FALSE) -> Bár | H15: =VLOOKUP($B15,__Ciselnik!$A$1:$E$202,5,FALSE) -> 1 | J15: 4 | K15: 4 | L15: 4 | M15: 4 | N15: 4 | AV15: 2 | AW15: 2 | AX15: 2 | AY15: 2 | BA15: 2 | BC15: 2 | BD15: 2 | BE15: 2 | BF15: 2 | BG15: 2 | BJ15: 0 | BK15: =BJ15-SUM(I15:BI15) -> -40 | BL15: =SUM(I15:M15) -> 16 | BM15: =SUM(N15:Q15) -> 4 | BN15: =SUM(R15:U15)+(2/4*V15) -> 0 | BO15: =SUM(W15:Z15)+(2/4*V15) -> 0 | BP15: =SUM(AA15:AD15) -> 0 | BQ15: =SUM(AE15:AH15)+(2/5*AI15) -> 0 | BR15: =SUM(AJ15:AM15)+(3/5*AI15) -> 0 | BS15: =SUM(AN15:AQ15)+(1/5*AR15) -> 0 | BT15: =SUM(AS15:AU15)+(4/5*AR15)+(2/4*AV15) -> 1 | BU15: =SUM(AW15:AZ15)+(2/4*AV15) -> 7 | BV15: =SUM(BA15:BD15)+(1/5*BE15) -> 6 | BW15: =SUM(BF15:BI15)+(4/5*BE15) -> 6 | BX15: =SUM(BL15:BW15) -> 40
A16: =VLOOKUP($B16,__Ciselnik!$A$1:$B$202,2,FALSE) -> ŘSD | B16: RSDVESTS | C16: =VLOOKUP($B16,__Ciselnik!$A$1:$H$202,7,FALSE) -> psc.sp98.rsdvest26-bc | D16: =VLOOKUP($B16,__Ciselnik!$A$1:$H$202,8,FALSE) -> psc.sp98.rsdvest26 | E16: =VLOOKUP($B16,__Ciselnik!$A$1:$I$202,9,FALSE) -> USYC.SP98 | F16: =VLOOKUP($B16,__Ciselnik!$A$1:$C$202,3,FALSE) -> VEST | G16: =VLOOKUP($B16,__Ciselnik!$A$1:$D$202,4,FALSE) -> Bár | H16: =VLOOKUP($B16,__Ciselnik!$A$1:$E$202,5,FALSE) -> 1 | J16: 8 | K16: 8 | L16: 8 | M16: 8 | N16: 8 | Q16: 8 | R16: 8 | S16: 16 | T16: 8 | U16: 8 | V16: 8 | W16: 8 | X16: 8 | Y16: 8 | Z16: 8 | AA16: 8 | AB16: 8 | AC16: 8 | AD16: 8 | AE16: 8 | AF16: 8 | AG16: 8 | AH16: 8 | AK16: 4 | AN16: 4 | AO16: 4 | AP16: 4 | AQ16: 4 | AR16: 4 | AS16: 4 | AT16: 4 | AU16: 4 | AV16: 4 | AW16: 4 | AX16: 4 | AY16: 4 | BA16: 4 | BC16: 4 | BD16: 4 | BE16: 4 | BF16: 4 | BG16: 4 | BJ16: 0 | BK16: =BJ16-SUM(I16:BI16) -> -268 | BL16: =SUM(I16:M16) -> 32 | BM16: =SUM(N16:Q16) -> 16 | BN16: =SUM(R16:U16)+(2/4*V16) -> 44 | BO16: =SUM(W16:Z16)+(2/4*V16) -> 36 | BP16: =SUM(AA16:AD16) -> 32 | BQ16: =SUM(AE16:AH16)+(2/5*AI16) -> 32 | BR16: =SUM(AJ16:AM16)+(3/5*AI16) -> 4 | BS16: =SUM(AN16:AQ16)+(1/5*AR16) -> 17 | BT16: =SUM(AS16:AU16)+(4/5*AR16)+(2/4*AV16) -> 17 | BU16: =SUM(AW16:AZ16)+(2/4*AV16) -> 14 | BV16: =SUM(BA16:BD16)+(1/5*BE16) -> 13 | BW16: =SUM(BF16:BI16)+(4/5*BE16) -> 11 | BX16: =SUM(BL16:BW16) -> 268
A17: =VLOOKUP($B17,__Ciselnik!$A$1:$B$202,2,FALSE) -> ČDT | B17: ČDT Servis 2026 | C17: =VLOOKUP($B17,__Ciselnik!$A$1:$H$202,7,FALSE) -> psc.cdt_s_25-bc | D17: =VLOOKUP($B17,__Ciselnik!$A$1:$H$202,8,FALSE) -> psc.sp97.cdt_25 | E17: =VLOOKUP($B17,__Ciselnik!$A$1:$I$202,9,FALSE) -> USYC.SP97 | F17: =VLOOKUP($B17,__Ciselnik!$A$1:$C$202,3,FALSE) -> Telco | G17: =VLOOKUP($B17,__Ciselnik!$A$1:$D$202,4,FALSE) -> Hauser | H17: =VLOOKUP($B17,__Ciselnik!$A$1:$E$202,5,FALSE) -> 1 | R17: 2 | S17: 2 | T17: 2 | U17: 2 | V17: 2 | W17: 2 | X17: 2 | Y17: 2 | Z17: 2 | AA17: 2 | AB17: 2 | AC17: 2 | AD17: 2 | AE17: 2 | AG17: 2 | AH17: 2 | AI17: 2 | AJ17: 2 | AK17: 2 | AL17: 2 | AM17: 2 | AP17: 2 | AQ17: 2 | AR17: 2 | AS17: 2 | AT17: 2 | AU17: 2 | AV17: 2 | AW17: 2 | AY17: 2 | AZ17: 2 | BA17: 2 | BB17: 2 | BC17: 2 | BD17: 2 | BE17: 2 | BF17: 2 | BG17: 2 | BJ17: 0 | BK17: =BJ17-SUM(I17:BI17) -> -76 | BL17: =SUM(I17:M17) -> 0 | BM17: =SUM(N17:Q17) -> 0 | BN17: =SUM(R17:U17)+(2/4*V17) -> 9 | BO17: =SUM(W17:Z17)+(2/4*V17) -> 9 | BP17: =SUM(AA17:AD17) -> 8 | BQ17: =SUM(AE17:AH17)+(2/5*AI17) -> 7 | BR17: =SUM(AJ17:AM17)+(3/5*AI17) -> 9 | BS17: =SUM(AN17:AQ17)+(1/5*AR17) -> 4 | BT17: =SUM(AS17:AU17)+(4/5*AR17)+(2/4*AV17) -> 9 | BU17: =SUM(AW17:AZ17)+(2/4*AV17) -> 7 | BV17: =SUM(BA17:BD17)+(1/5*BE17) -> 8 | BW17: =SUM(BF17:BI17)+(4/5*BE17) -> 6 | BX17: =SUM(BL17:BW17) -> 76
A18: =VLOOKUP($B18,__Ciselnik!$A$1:$B$202,2,FALSE) -> ČDT | B18: ČDT - Změnové požadavky 2026 | C18: =VLOOKUP($B18,__Ciselnik!$A$1:$H$202,7,FALSE) -> psc.cdt_s_25-bc | D18: =VLOOKUP($B18,__Ciselnik!$A$1:$H$202,8,FALSE) -> psc.sp97.cdt_25 | E18: =VLOOKUP($B18,__Ciselnik!$A$1:$I$202,9,FALSE) -> USYC.SP97 | F18: =VLOOKUP($B18,__Ciselnik!$A$1:$C$202,3,FALSE) -> Telco | G18: =VLOOKUP($B18,__Ciselnik!$A$1:$D$202,4,FALSE) -> Hauser | H18: =VLOOKUP($B18,__Ciselnik!$A$1:$E$202,5,FALSE) -> 1 | R18: 0 | S18: 4 | T18: 4 | U18: 4 | V18: 0 | W18: 0 | X18: 0 | Y18: 0 | Z18: 0 | AA18: 0 | AB18: 0 | AC18: 0 | AD18: 0 | AE18: 0 | AF18: 0 | AG18: 0 | AH18: 0 | AI18: 0 | AJ18: 0 | AK18: 0 | AL18: 0 | AM18: 0 | AN18: 0 | AO18: 0 | AP18: 0 | AQ18: 0 | AR18: 0 | AS18: 0 | AT18: 0 | AU18: 0 | AV18: 0 | AW18: 0 | AX18: 0 | AY18: 0 | AZ18: 0 | BA18: 0 | BB18: 0 | BC18: 0 | BD18: 0 | BE18: 0 | BF18: 0 | BG18: 0 | BJ18: 0 | BK18: =BJ18-SUM(I18:BI18) -> -12 | BL18: =SUM(I18:M18) -> 0 | BM18: =SUM(N18:Q18) -> 0 | BN18: =SUM(R18:U18)+(2/4*V18) -> 12 | BO18: =SUM(W18:Z18)+(2/4*V18) -> 0 | BP18: =SUM(AA18:AD18) -> 0 | BQ18: =SUM(AE18:AH18)+(2/5*AI18) -> 0 | BR18: =SUM(AJ18:AM18)+(3/5*AI18) -> 0 | BS18: =SUM(AN18:AQ18)+(1/5*AR18) -> 0 | BT18: =SUM(AS18:AU18)+(4/5*AR18)+(2/4*AV18) -> 0 | BU18: =SUM(AW18:AZ18)+(2/4*AV18) -> 0 | BV18: =SUM(BA18:BD18)+(1/5*BE18) -> 0 | BW18: =SUM(BF18:BI18)+(4/5*BE18) -> 0 | BX18: =SUM(BL18:BW18) -> 12
A19: =VLOOKUP($B19,__Ciselnik!$A$1:$B$202,2,FALSE) -> ČDT | B19: ČDT - Contracting 2025 | C19: =VLOOKUP($B19,__Ciselnik!$A$1:$H$202,7,FALSE) -> psc.cdt_s_25-bc | D19: =VLOOKUP($B19,__Ciselnik!$A$1:$H$202,8,FALSE) -> psc.sp97.cdt_25 | E19: =VLOOKUP($B19,__Ciselnik!$A$1:$I$202,9,FALSE) -> USYC.SP97 | F19: =VLOOKUP($B19,__Ciselnik!$A$1:$C$202,3,FALSE) -> Telco | G19: =VLOOKUP($B19,__Ciselnik!$A$1:$D$202,4,FALSE) -> Hauser | H19: =VLOOKUP($B19,__Ciselnik!$A$1:$E$202,5,FALSE) -> 1 | BJ19: 0 | BK19: =BJ19-SUM(I19:BI19) -> 0 | BL19: =SUM(I19:M19) -> 0 | BM19: =SUM(N19:Q19) -> 0 | BN19: =SUM(R19:U19)+(2/4*V19) -> #VALUE! | BO19: =SUM(W19:Z19)+(2/4*V19) -> #VALUE! | BP19: =SUM(AA19:AD19) -> 0 | BQ19: =SUM(AE19:AH19)+(2/5*AI19) -> #VALUE! | BR19: =SUM(AJ19:AM19)+(3/5*AI19) -> #VALUE! | BS19: =SUM(AN19:AQ19)+(1/5*AR19) -> #VALUE! | BT19: =SUM(AS19:AU19)+(4/5*AR19)+(2/4*AV19) -> #VALUE! | BU19: =SUM(AW19:AZ19)+(2/4*AV19) -> #VALUE! | BV19: =SUM(BA19:BD19)+(1/5*BE19) -> #VALUE! | BW19: =SUM(BF19:BI19)+(4/5*BE19) -> #VALUE! | BX19: =SUM(BL19:BW19) -> #VALUE!
B20: GASNET_GDO | I20: 0 | J20: 4 | K20: 4 | L20: 4 | M20: 0 | N20: 0 | O20: 0 | P20: 0

Sheet Budinská
A1: =RIGHT(CELL("názevsouboru"),LEN(CELL("názevsouboru"))-FIND("]",CELL("názevsouboru"))) -> Faflík | B1: PM | I1: =__Ciselnik!L2 -> 45292 | N1: =EDATE(I1,1) -> 45323 | R1: =EDATE(N1,1) -> 45352 | V1: =EDATE(R1,1) -> 45383 | AA1: =EDATE(V1,1) -> 45413 | AE1: =EDATE(AA1,1) -> 45444 | AI1: =EDATE(AE1,1) -> 45474 | AN1: =EDATE(AI1,1) -> 45505 | AR1: =EDATE(AN1,1) -> 45536 | AV1: =EDATE(AR1,1) -> 45566 | BA1: =EDATE(AV1,1) -> 45597 | BE1: =EDATE(BA1,1) -> 45627 | BL1: Plánované hodiny celkem
A2: Kurátor: | B2: Leona B. | G2: Týden | I2: 1 | J2: 2 | K2: 3 | L2: 4 | M2: 5 | N2: 6 | O2: 7 | P2: 8 | Q2: 9 | R2: 10 | S2: 11 | T2: 12 | U2: 13 | V2: 14 | W2: 15 | X2: 16 | Y2: 17 | Z2: 18 | AA2: 19 | AB2: 20 | AC2: 21 | AD2: 22 | AE2: 23 | AF2: 24 | AG2: 25 | AH2: 26 | AI2: 27 | AJ2: 28 | AK2: 29 | AL2: 30 | AM2: 31 | AN2: 32 | AO2: 33 | AP2: 34 | AQ2: 35 | AR2: 36 | AS2: 37 | AT2: 38 | AU2: 39 | AV2: 40 | AW2: 41 | AX2: 42 | AY2: 43 | AZ2: 44 | BA2: 45 | BB2: 46 | BC2: 47 | BD2: 48 | BE2: 49 | BF2: 50 | BG2: 51 | BH2: 52 | BI2: 53 | BL2: =__Ciselnik!L2 -> 45292 | BM2: =EDATE(BL2,1) -> 45323 | BN2: =EDATE(BM2,1) -> 45352 | BO2: =EDATE(BN2,1) -> 45383 | BP2: =EDATE(BO2,1) -> 45413 | BQ2: =EDATE(BP2,1) -> 45444 | BR2: =EDATE(BQ2,1) -> 45474 | BS2: =EDATE(BR2,1) -> 45505 | BT2: =EDATE(BS2,1) -> 45536 | ... BW2: =EDATE(BV2,1) -> 45627 | BX2: 2026
A3: Jednotka: | B3: energo | G3: Kapacita | I3: 8 | J3: 40 | K3: 40 | L3: 40 | M3: 40 | N3: 40 | O3: 40 | P3: 40 | Q3: 40 | R3: 40 | S3: 40 | T3: 40 | U3: 40 | V3: 32 | W3: 32 | X3: 40 | Y3: 40 | Z3: 32 | AA3: 32 | AB3: 40 | AC3: 40 | AD3: 40 | AE3: 40 | AF3: 40 | AG3: 40 | AH3: 40 | AI3: 40 | AJ3: 32 | AK3: 40 | AL3: 40 | AM3: 40 | AN3: 40 | AO3: 40 | AP3: 40 | AQ3: 40 | AR3: 40 | AS3: 40 | AT3: 40 | AU3: 40 | AV3: 32 | AW3: 40 | AX3: 40 | AY3: 40 | AZ3: 32 | BA3: 40 | BB3: 40 | BC3: 32 | BD3: 40 | BE3: 40 | BF3: 40 | BG3: 40 | BH3: 24 | BI3: 32 | BL3: =SUM(I3:M3) -> 168 | BM3: =SUM(N3:Q3) -> 160 | BN3: =SUM(R3:U3)+(2/4*V3) -> 176 | BO3: =SUM(W3:Z3)+(2/4*V3) -> 160 | BP3: =SUM(AA3:AD3) -> 152 | BQ3: =SUM(AE3:AH3)+(2/5*AI3) -> 176 | BR3: =SUM(AJ3:AM3)+(3/5*AI3) -> 176 | BS3: =SUM(AN3:AQ3)+(1/5*AR3) -> 168 | BT3: =SUM(AS3:AU3)+(4/5*AR3)+(2/4*AV3) -> 168 | BU3: =SUM(AW3:AZ3)+(2/4*AV3) -> 168 | BV3: =SUM(BA3:BD3)+(1/5*BE3) -> 160 | BW3: =SUM(BF3:BI3)+(4/5*BE3) -> 168 | BX3: =SUM(BL3:BW3) -> 2000
A4: Generovat | B4: Ne | G4: Volná kapacita | I4: =I3-I5 -> 0 | J4: =J3-J5 -> 5 | K4: =K3-K5 -> 0 | L4: =L3-L5 -> 0 | M4: =M3-M5 -> -3 | N4: =N3-N5 -> 0 | O4: =O3-O5 -> 10 | P4: =P3-P5 -> -10 | ... BI4: =BI3-BI5 -> 0 | BL4: =BL3-BL5 -> -4 | BM4: =BM3-BM5 -> -16 | BN4: =BN3-BN5 -> #REF! | BO4: =BO3-BO5 -> #REF! | BP4: =BP3-BP5 -> -30 | BQ4: =BQ3-BQ5 -> -40 | BR4: =BR3-BR5 -> -40 | BS4: =BS3-BS5 -> -21 | ... BW4: =BW3-BW5 -> -31 | BX4: =SUM(BL4:BW4) -> #REF!
G5: Celkové vytížení | I5: =SUMPRODUCT(I10:I35,$H$10:$H$35) -> 8 | J5: =SUMPRODUCT(J10:J35,$H$10:$H$35) -> 35 | K5: =SUMPRODUCT(K10:K35,$H$10:$H$35) -> 40 | L5: =SUMPRODUCT(L10:L35,$H$10:$H$35) -> 40 | M5: =SUMPRODUCT(M10:M35,$H$10:$H$35) -> 43 | N5: =SUMPRODUCT(N10:N35,$H$10:$H$35) -> 40 | O5: =SUMPRODUCT(O10:O35,$H$10:$H$35) -> 30 | P5: =SUMPRODUCT(P10:P35,$H$10:$H$35) -> 50 | ... BI5: =SUMPRODUCT(BI10:BI35,$H$10:$H$35) -> 32 | BL5: =SUM(BL10:BL35) -> 172 | BM5: =SUM(BM10:BM35) -> 176 | BN5: =SUM(BN10:BN35) -> #REF! | BO5: =SUM(BO10:BO35) -> #REF! | BP5: =SUM(BP10:BP35) -> 182 | BQ5: =SUM(BQ10:BQ35) -> 216 | BR5: =SUM(BR10:BR35) -> 216 | BS5: =SUM(BS10:BS35) -> 189 | ... BX5: =SUM(BX10:BX35) -> #REF!
G6: V rámci SP97 | I6: {=SUMPRODUCT(I10:I35,$H$10:$H$35*($E$10:$E$35="USYC.SP97"))} -> 0 | J6: {=SUMPRODUCT(J10:J35,$H$10:$H$35*($E$10:$E$35="USYC.SP97"))} -> 18 | K6: {=SUMPRODUCT(K10:K35,$H$10:$H$35*($E$10:$E$35="USYC.SP97"))} -> 18 | L6: {=SUMPRODUCT(L10:L35,$H$10:$H$35*($E$10:$E$35="USYC.SP97"))} -> 18 | M6: {=SUMPRODUCT(M10:M35,$H$10:$H$35*($E$10:$E$35="USYC.SP97"))} -> 18 | N6: {=SUMPRODUCT(N10:N35,$H$10:$H$35*($E$10:$E$35="USYC.SP97"))} -> 14 | O6: {=SUMPRODUCT(O10:O35,$H$10:$H$35*($E$10:$E$35="USYC.SP97"))} -> 12 | P6: {=SUMPRODUCT(P10:P35,$H$10:$H$35*($E$10:$E$35="USYC.SP97"))} -> 32 | ... BI6: {=SUMPRODUCT(BI10:BI35,$H$10:$H$35*($E$10:$E$35="USYC.SP97"))} -> 0 | BL6: =SUMIF($E$10:$E$35,"USYC.SP97",BL10:BL35) -> 72 | BM6: =SUMIF($E$10:$E$35,"USYC.SP97",BM10:BM35) -> 86 | BN6: =SUMIF($E$10:$E$35,"USYC.SP97",BN10:BN35) -> 114 | BO6: =SUMIF($E$10:$E$35,"USYC.SP97",BO10:BO35) -> 108 | BP6: =SUMIF($E$10:$E$35,"USYC.SP97",BP10:BP35) -> 96 | BQ6: =SUMIF($E$10:$E$35,"USYC.SP97",BQ10:BQ35) -> 101 | BR6: =SUMIF($E$10:$E$35,"USYC.SP97",BR10:BR35) -> 79 | BS6: =SUMIF($E$10:$E$35,"USYC.SP97",BS10:BS35) -> 84 | ... BX6: =SUMIF($E$10:$E$35,"USYC.SP97",BX10:BX35) -> 1076
G7: V rámci SP98 | I7: {=SUMPRODUCT(I10:I35,$H$10:$H$35*($E$10:$E$35="USYC.SP98"))} -> 0 | J7: {=SUMPRODUCT(J10:J35,$H$10:$H$35*($E$10:$E$35="USYC.SP98"))} -> 9 | K7: {=SUMPRODUCT(K10:K35,$H$10:$H$35*($E$10:$E$35="USYC.SP98"))} -> 14 | L7: {=SUMPRODUCT(L10:L35,$H$10:$H$35*($E$10:$E$35="USYC.SP98"))} -> 12 | M7: {=SUMPRODUCT(M10:M35,$H$10:$H$35*($E$10:$E$35="USYC.SP98"))} -> 15 | N7: {=SUMPRODUCT(N10:N35,$H$10:$H$35*($E$10:$E$35="USYC.SP98"))} -> 16 | O7: {=SUMPRODUCT(O10:O35,$H$10:$H$35*($E$10:$E$35="USYC.SP98"))} -> 10 | P7: {=SUMPRODUCT(P10:P35,$H$10:$H$35*($E$10:$E$35="USYC.SP98"))} -> 10 | ... BI7: {=SUMPRODUCT(BI10:BI35,$H$10:$H$35*($E$10:$E$35="USYC.SP98"))} -> 0 | BL7: =SUMIF($E$10:$E$35,"USYC.SP98",BL10:BL35) -> 56 | BM7: =SUMIF($E$10:$E$35,"USYC.SP98",BM10:BM35) -> 56 | BN7: =SUMIF($E$10:$E$35,"USYC.SP98",BN10:BN35) -> #REF! | BO7: =SUMIF($E$10:$E$35,"USYC.SP98",BO10:BO35) -> #REF! | BP7: =SUMIF($E$10:$E$35,"USYC.SP98",BP10:BP35) -> 62 | BQ7: =SUMIF($E$10:$E$35,"USYC.SP98",BQ10:BQ35) -> 67 | BR7: =SUMIF($E$10:$E$35,"USYC.SP98",BR10:BR35) -> 57 | BS7: =SUMIF($E$10:$E$35,"USYC.SP98",BS10:BS35) -> 71 | ... BX7: =SUMIF($E$10:$E$35,"USYC.SP98",BX10:BX35) -> #REF!
G8: Externě | I8: {=SUMPRODUCT(I10:I35,$H$10:$H$35*($E$10:$E$35="Ext"))} -> 8 | J8: {=SUMPRODUCT(J10:J35,$H$10:$H$35*($E$10:$E$35="Ext"))} -> 8 | K8: {=SUMPRODUCT(K10:K35,$H$10:$H$35*($E$10:$E$35="Ext"))} -> 8 | L8: {=SUMPRODUCT(L10:L35,$H$10:$H$35*($E$10:$E$35="Ext"))} -> 10 | M8: {=SUMPRODUCT(M10:M35,$H$10:$H$35*($E$10:$E$35="Ext"))} -> 10 | N8: {=SUMPRODUCT(N10:N35,$H$10:$H$35*($E$10:$E$35="Ext"))} -> 10 | O8: {=SUMPRODUCT(O10:O35,$H$10:$H$35*($E$10:$E$35="Ext"))} -> 8 | P8: {=SUMPRODUCT(P10:P35,$H$10:$H$35*($E$10:$E$35="Ext"))} -> 8 | ... BI8: {=SUMPRODUCT(BI10:BI35,$H$10:$H$35*($E$10:$E$35="Ext"))} -> 32 | BL8: =SUMIF($E$10:$E$35,"Ext",BL10:BL35) -> 44 | BM8: =SUMIF($E$10:$E$35,"Ext",BM10:BM35) -> 34 | BN8: =SUMIF($E$10:$E$35,"Ext",BN10:BN35) -> 27 | BO8: =SUMIF($E$10:$E$35,"Ext",BO10:BO35) -> 27 | BP8: =SUMIF($E$10:$E$35,"Ext",BP10:BP35) -> 24 | BQ8: =SUMIF($E$10:$E$35,"Ext",BQ10:BQ35) -> 48 | BR8: =SUMIF($E$10:$E$35,"Ext",BR10:BR35) -> 80 | BS8: =SUMIF($E$10:$E$35,"Ext",BS10:BS35) -> 34 | ... BX8: =SUMIF($E$10:$E$35,"Ext",BX10:BX35) -> 516
A9: Klient | B9: Projekt | C9: BC | D9: Deal Unit | E9: Jednotka | F9: Oblast | G9: PM | H9: Koef. | I9: - | J9: - | K9: - | L9: - | M9: - | N9: - | O9: - | P9: - | Q9: - | R9: - | S9: - | T9: - | U9: - | V9: - | W9: - | X9: - | Y9: - | Z9: - | AA9: - | AB9: - | AC9: - | AD9: - | AE9: - | AF9: - | AG9: - | AH9: - | AI9: - | AJ9: - | AK9: - | AL9: - | AM9: - | AN9: - | AO9: - | AP9: - | AQ9: - | AR9: - | AS9: - | AT9: - | AU9: - | AV9: - | AW9: - | AX9: - | AY9: - | AZ9: - | BA9: - | BB9: - | BC9: - | BD9: - | BE9: - | BF9: - | BG9: - | BH9: - | BI9: - | BJ9: Plán | BK9: Zbývá
A10: =VLOOKUP($B10,__Ciselnik!$A$1:$B$202,2,FALSE) -> - | B10: =__Ciselnik!A2 -> _aktivity mimo Geo | C10: =VLOOKUP($B10,__Ciselnik!$A$1:$H$202,7,FALSE) -> - | D10: =VLOOKUP($B10,__Ciselnik!$A$1:$H$202,8,FALSE) -> - | E10: =VLOOKUP($B10,__Ciselnik!$A$1:$I$202,9,FALSE) -> Ext | F10: =VLOOKUP($B10,__Ciselnik!$A$1:$C$202,3,FALSE) -> - | G10: =VLOOKUP($B10,__Ciselnik!$A$1:$D$202,4,FALSE) -> - | H10: =VLOOKUP($B10,__Ciselnik!$A$1:$E$202,5,FALSE) -> 1 | J10: 8 | K10: 8 | L10: 10 | M10: 10 | N10: 10 | O10: 8 | P10: 8 | Q10: 8 | R10: 6 | S10: 6 | T10: 6 | U10: 6 | V10: 6 | W10: 6 | X10: 6 | Y10: 6 | Z10: 6 | AA10: 6 | AB10: 6 | AC10: 6 | AD10: 6 | AE10: 8 | AF10: 8 | AG10: 8 | AH10: 8 | AK10: 8 | AL10: 8 | AM10: 8 | AN10: 8 | AO10: 8 | AP10: 8 | AQ10: 8 | AR10: 8 | AS10: 8 | AT10: 8 | AU10: 8 | AV10: 8 | AW10: 8 | AX10: 8 | AY10: 8 | BA10: 8 | BB10: 8 | BC10: 8 | BD10: 8 | BE10: 8 | BF10: 8 | BG10: 8 | BK10: =BJ10-SUM(I10:BI10) -> -356 | BL10: =SUM(I10:M10) -> 36 | BM10: =SUM(N10:Q10) -> 34 | BN10: =SUM(R10:U10)+(2/4*V10) -> 27 | BO10: =SUM(W10:Z10)+(2/4*V10) -> 27 | BP10: =SUM(AA10:AD10) -> 24 | BQ10: =SUM(AE10:AH10)+(2/5*AI10) -> 32 | BR10: =SUM(AJ10:AM10)+(3/5*AI10) -> 24 | BS10: =SUM(AN10:AQ10)+(1/5*AR10) -> 34 | BT10: =SUM(AS10:AU10)+(4/5*AR10)+(2/4*AV10) -> 34 | BU10: =SUM(AW10:AZ10)+(2/4*AV10) -> 28 | BV10: =SUM(BA10:BD10)+(1/5*BE10) -> 34 | BW10: =SUM(BF10:BI10)+(4/5*BE10) -> 22 | BX10: =SUM(BL10:BW10) -> 356
A11: =VLOOKUP($B11,__Ciselnik!$A$1:$B$202,2,FALSE) -> - | B11: =__Ciselnik!A3 -> _dovolená/nemoc | C11: =VLOOKUP($B11,__Ciselnik!$A$1:$H$202,7,FALSE) -> - | D11: =VLOOKUP($B11,__Ciselnik!$A$1:$H$202,8,FALSE) -> - | E11: =VLOOKUP($B11,__Ciselnik!$A$1:$I$202,9,FALSE) -> Ext | F11: =VLOOKUP($B11,__Ciselnik!$A$1:$C$202,3,FALSE) -> - | G11: =VLOOKUP($B11,__Ciselnik!$A$1:$D$202,4,FALSE) -> - | H11: =VLOOKUP($B11,__Ciselnik!$A$1:$E$202,5,FALSE) -> 1 | I11: 8 | AI11: 40 | AJ11: 32 | AZ11: 16 | BC11: 8 | BH11: 24 | BI11: 32 | BJ11: 200 | BK11: =BJ11-SUM(I11:BI11) -> 40 | BL11: =SUM(I11:M11) -> 8 | BM11: =SUM(N11:Q11) -> 0 | BN11: =SUM(R11:U11)+(2/4*V11) -> 0 | BO11: =SUM(W11:Z11)+(2/4*V11) -> 0 | BP11: =SUM(AA11:AD11) -> 0 | BQ11: =SUM(AE11:AH11)+(2/5*AI11) -> 16 | BR11: =SUM(AJ11:AM11)+(3/5*AI11) -> 56 | BS11: =SUM(AN11:AQ11)+(1/5*AR11) -> 0 | BT11: =SUM(AS11:AU11)+(4/5*AR11)+(2/4*AV11) -> 0 | BU11: =SUM(AW11:AZ11)+(2/4*AV11) -> 16 | BV11: =SUM(BA11:BD11)+(1/5*BE11) -> 8 | BW11: =SUM(BF11:BI11)+(4/5*BE11) -> 56 | BX11: =SUM(BL11:BW11) -> 160
A12: =VLOOKUP($B12,__Ciselnik!$A$1:$B$202,2,FALSE) -> - | B12: _presale 98 | C12: =VLOOKUP($B12,__Ciselnik!$A$1:$H$202,7,FALSE) -> psc.sp98.presale-bc | D12: =VLOOKUP($B12,__Ciselnik!$A$1:$H$202,8,FALSE) -> - | E12: =VLOOKUP($B12,__Ciselnik!$A$1:$I$202,9,FALSE) -> USYC.SP98 | F12: =VLOOKUP($B12,__Ciselnik!$A$1:$C$202,3,FALSE) -> - | G12: =VLOOKUP($B12,__Ciselnik!$A$1:$D$202,4,FALSE) -> - | H12: =VLOOKUP($B12,__Ciselnik!$A$1:$E$202,5,FALSE) -> 1 | BK12: =BJ12-SUM(I12:BI12) -> 0 | BL12: =SUM(I12:M12) -> 0 | BM12: =SUM(N12:Q12) -> 0 | BN12: =SUM(R12:U12)+(2/4*V12) -> 0 | BO12: =SUM(W12:Z12)+(2/4*V12) -> 0 | BP12: =SUM(AA12:AD12) -> 0 | BQ12: =SUM(AE12:AH12)+(2/5*AI12) -> 0 | BR12: =SUM(AJ12:AM12)+(3/5*AI12) -> 0 | BS12: =SUM(AN12:AQ12)+(1/5*AR12) -> 0 | BT12: =SUM(AS12:AU12)+(4/5*AR12)+(2/4*AV12) -> 0 | BU12: =SUM(AW12:AZ12)+(2/4*AV12) -> 0 | BV12: =SUM(BA12:BD12)+(1/5*BE12) -> 0 | BW12: =SUM(BF12:BI12)+(4/5*BE12) -> 0 | BX12: =SUM(BL12:BW12) -> 0
A13: =VLOOKUP($B13,__Ciselnik!$A$1:$B$202,2,FALSE) -> - | B13: =__Ciselnik!A7 -> _režie | C13: =VLOOKUP($B13,__Ciselnik!$A$1:$H$202,7,FALSE) -> - | D13: =VLOOKUP($B13,__Ciselnik!$A$1:$H$202,8,FALSE) -> - | E13: =VLOOKUP($B13,__Ciselnik!$A$1:$I$202,9,FALSE) -> Ext | F13: =VLOOKUP($B13,__Ciselnik!$A$1:$C$202,3,FALSE) -> - | G13: =VLOOKUP($B13,__Ciselnik!$A$1:$D$202,4,FALSE) -> - | H13: =VLOOKUP($B13,__Ciselnik!$A$1:$E$202,5,FALSE) -> 1 | BK13: =BJ13-SUM(I13:BI13) -> 0 | BL13: =SUM(I13:M13) -> 0 | BM13: =SUM(N13:Q13) -> 0 | BN13: =SUM(R13:U13)+(2/4*V13) -> 0 | BO13: =SUM(W13:Z13)+(2/4*V13) -> 0 | BP13: =SUM(AA13:AD13) -> 0 | BQ13: =SUM(AE13:AH13)+(2/5*AI13) -> 0 | BR13: =SUM(AJ13:AM13)+(3/5*AI13) -> 0 | BS13: =SUM(AN13:AQ13)+(1/5*AR13) -> 0 | BT13: =SUM(AS13:AU13)+(4/5*AR13)+(2/4*AV13) -> 0 | BU13: =SUM(AW13:AZ13)+(2/4*AV13) -> 0 | BV13: =SUM(BA13:BD13)+(1/5*BE13) -> 0 | BW13: =SUM(BF13:BI13)+(4/5*BE13) -> 0 | BX13: =SUM(BL13:BW13) -> 0
A14: =VLOOKUP($B14,__Ciselnik!$A$1:$B$202,2,FALSE) -> TMobile | B14: TMCZ Výstavba 2026 | C14: =VLOOKUP($B14,__Ciselnik!$A$1:$H$202,7,FALSE) -> psc.tmcz_constr_25-bc | D14: =VLOOKUP($B14,__Ciselnik!$A$1:$H$202,8,FALSE) -> psc.sp97.tmobile_25 | E14: =VLOOKUP($B14,__Ciselnik!$A$1:$I$202,9,FALSE) -> USYC.SP97 | F14: =VLOOKUP($B14,__Ciselnik!$A$1:$C$202,3,FALSE) -> Ostatní | G14: =VLOOKUP($B14,__Ciselnik!$A$1:$D$202,4,FALSE) -> Budinská | H14: =VLOOKUP($B14,__Ciselnik!$A$1:$E$202,5,FALSE) -> 1 | J14: 10 | K14: 10 | L14: 10 | M14: 10 | N14: 10 | O14: 8 | P14: 8 | Q14: 8 | R14: 8 | S14: 8 | T14: 8 | U14: 8 | V14: 8 | W14: 8 | X14: 8 | Y14: 8 | Z14: 8 | AA14: 8 | AB14: 8 | AC14: 8 | AD14: 8 | AE14: 8 | AF14: 8 | AG14: 8 | AH14: 8 | AK14: 8 | AL14: 8 | AM14: 8 | AN14: 8 | AO14: 8 | AP14: 8 | AQ14: 8 | AR14: 8 | AS14: 8 | AT14: 8 | AU14: 8 | AV14: 8 | AW14: 8 | AX14: 8 | AY14: 8 | AZ14: 8 | BA14: 8 | BB14: 8 | BC14: 8 | BD14: 8 | BE14: 8 | BF14: 8 | BG14: 8 | BH14: 8 | BJ14: 0 | BK14: =BJ14-SUM(I14:BI14) -> -402 | BL14: =SUM(I14:M14) -> 40 | BM14: =SUM(N14:Q14) -> 34 | BN14: =SUM(R14:U14)+(2/4*V14) -> 36 | BO14: =SUM(W14:Z14)+(2/4*V14) -> 36 | BP14: =SUM(AA14:AD14) -> 32 | BQ14: =SUM(AE14:AH14)+(2/5*AI14) -> 32 | BR14: =SUM(AJ14:AM14)+(3/5*AI14) -> 24 | BS14: =SUM(AN14:AQ14)+(1/5*AR14) -> 34 | BT14: =SUM(AS14:AU14)+(4/5*AR14)+(2/4*AV14) -> 34 | BU14: =SUM(AW14:AZ14)+(2/4*AV14) -> 36 | BV14: =SUM(BA14:BD14)+(1/5*BE14) -> 34 | BW14: =SUM(BF14:BI14)+(4/5*BE14) -> 30 | BX14: =SUM(BL14:BW14) -> 402
A15: =VLOOKUP($B15,__Ciselnik!$A$1:$B$202,2,FALSE) -> Unipetrol,GS | B15: AMI26 | C15: =VLOOKUP($B15,__Ciselnik!$A$1:$H$202,7,FALSE) -> psc.sp98.ami25-bc | D15: =VLOOKUP($B15,__Ciselnik!$A$1:$H$202,8,FALSE) -> psc.sp98.ami25 | E15: =VLOOKUP($B15,__Ciselnik!$A$1:$I$202,9,FALSE) -> USYC.SP98 | F15: =VLOOKUP($B15,__Ciselnik!$A$1:$C$202,3,FALSE) -> AMI | G15: =VLOOKUP($B15,__Ciselnik!$A$1:$D$202,4,FALSE) -> Budinská | H15: =VLOOKUP($B15,__Ciselnik!$A$1:$E$202,5,FALSE) -> 1 | N15: 4 | O15: 2 | P15: 2 | Q15: 2 | R15: 2 | S15: 2 | T15: 2 | U15: 2 | V15: 2 | W15: 2 | X15: 2 | Y15: 2 | Z15: 2 | AA15: 2 | AB15: 4 | AC15: 4 | AD15: 4 | AE15: 4 | AF15: 4 | AG15: 4 | AH15: 4 | AI15: 4 | AJ15: 4 | AK15: 4 | AL15: 4 | AM15: 4 | AN15: 4 | AO15: 4 | AP15: 4 | AQ15: 4 | AR15: 4 | AS15: 4 | AT15: 4 | AU15: 4 | AV15: 4 | AW15: 4 | AX15: 4 | AY15: 4 | AZ15: 4 | BA15: 4 | BB15: 4 | BC15: 4 | BD15: 4 | BE15: 4 | BF15: 4 | BG15: 4 | BH15: 4 | BJ15: 0 | BK15: =BJ15-SUM(I15:BI15) -> -162 | BL15: =SUM(I15:M15) -> 0 | BM15: =SUM(N15:Q15) -> 10 | BN15: =SUM(R15:U15)+(2/4*V15) -> 9 | BO15: =SUM(W15:Z15)+(2/4*V15) -> 9 | BP15: =SUM(AA15:AD15) -> 14 | BQ15: =SUM(AE15:AH15)+(2/5*AI15) -> 18 | BR15: =SUM(AJ15:AM15)+(3/5*AI15) -> 18 | BS15: =SUM(AN15:AQ15)+(1/5*AR15) -> 17 | BT15: =SUM(AS15:AU15)+(4/5*AR15)+(2/4*AV15) -> 17 | BU15: =SUM(AW15:AZ15)+(2/4*AV15) -> 18 | BV15: =SUM(BA15:BD15)+(1/5*BE15) -> 17 | BW15: =SUM(BF15:BI15)+(4/5*BE15) -> 15 | BX15: =SUM(BL15:BW15) -> 162
A16: =VLOOKUP($B16,__Ciselnik!$A$1:$B$202,2,FALSE) -> VSD | B16: VSD26 | C16: =VLOOKUP($B16,__Ciselnik!$A$1:$H$202,7,FALSE) -> psc.sp98.vsd25-bc | D16: =VLOOKUP($B16,__Ciselnik!$A$1:$H$202,8,FALSE) -> psc.sp98.vsd25 | E16: =VLOOKUP($B16,__Ciselnik!$A$1:$I$202,9,FALSE) -> USYC.SP98 | F16: =VLOOKUP($B16,__Ciselnik!$A$1:$C$202,3,FALSE) -> Esri | G16: =VLOOKUP($B16,__Ciselnik!$A$1:$D$202,4,FALSE) -> Budinská | H16: =VLOOKUP($B16,__Ciselnik!$A$1:$E$202,5,FALSE) -> 1 | J16: 1 | K16: 2 | M16: 1 | T16: 2 | Y16: 2 | AB16: 2 | AC16: 1 | AD16: 1 | AE16: 1 | AG16: 1 | AH16: 1 | AK16: 2 | AM16: 1 | AN16: 1 | AO16: 2 | AP16: 1 | AQ16: 2 | AT16: 2 | AV16: 1 | AW16: 2 | AY16: 2 | AZ16: 2 | BB16: 2 | BC16: 1 | BD16: 2 | BE16: 1 | BG16: 1 | BJ16: 0 | BK16: =BJ16-SUM(I16:BI16) -> -40 | BL16: =SUM(I16:M16) -> 4 | BM16: =SUM(N16:Q16) -> 0 | BN16: =SUM(R16:U16)+(2/4*V16) -> 2 | BO16: =SUM(W16:Z16)+(2/4*V16) -> 2 | BP16: =SUM(AA16:AD16) -> 4 | BQ16: =SUM(AE16:AH16)+(2/5*AI16) -> 3 | BR16: =SUM(AJ16:AM16)+(3/5*AI16) -> 3 | BS16: =SUM(AN16:AQ16)+(1/5*AR16) -> 6 | BT16: =SUM(AS16:AU16)+(4/5*AR16)+(2/4*AV16) -> 3 | BU16: =SUM(AW16:AZ16)+(2/4*AV16) -> 7 | BV16: =SUM(BA16:BD16)+(1/5*BE16) -> 5 | BW16: =SUM(BF16:BI16)+(4/5*BE16) -> 2 | BX16: =SUM(BL16:BW16) -> 41
A17: =VLOOKUP($B17,__Ciselnik!$A$1:$B$202,2,FALSE) -> ČEPRO | B17: CEPRO26 | C17: =VLOOKUP($B17,__Ciselnik!$A$1:$H$202,7,FALSE) -> psc.sp98.cepro25-bc | D17: =VLOOKUP($B17,__Ciselnik!$A$1:$H$202,8,FALSE) -> psc.sp98.cepro25 | E17: =VLOOKUP($B17,__Ciselnik!$A$1:$I$202,9,FALSE) -> USYC.SP98 | F17: =VLOOKUP($B17,__Ciselnik!$A$1:$C$202,3,FALSE) -> Esri | G17: =VLOOKUP($B17,__Ciselnik!$A$1:$D$202,4,FALSE) -> Budinská | H17: =VLOOKUP($B17,__Ciselnik!$A$1:$E$202,5,FALSE) -> 1 | M17: 2 | U17: 2 | Z17: 2 | AD17: 1 | AH17: 2 | AM17: 2 | AQ17: 2 | AU17: 2 | AZ17: 2 | BD17: 2 | BJ17: 0 | BK17: =BJ17-SUM(I17:BI17) -> -19 | BL17: =SUM(I17:M17) -> 2 | BM17: =SUM(N17:Q17) -> 0 | BN17: =SUM(R17:U17)+(2/4*V17) -> 2 | BO17: =SUM(W17:Z17)+(2/4*V17) -> 2 | BP17: =SUM(AA17:AD17) -> 1 | BQ17: =SUM(AE17:AH17)+(2/5*AI17) -> 2 | BR17: =SUM(AJ17:AM17)+(3/5*AI17) -> 2 | BS17: =SUM(AN17:AQ17)+(1/5*AR17) -> 2 | BT17: =SUM(AS17:AU17)+(4/5*AR17)+(2/4*AV17) -> 2 | BU17: =SUM(AW17:AZ17)+(2/4*AV17) -> 2 | BV17: =SUM(BA17:BD17)+(1/5*BE17) -> 2 | BW17: =SUM(BF17:BI17)+(4/5*BE17) -> 0 | BX17: =SUM(BL17:BW17) -> 19
A18: =VLOOKUP($B18,__Ciselnik!$A$1:$B$202,2,FALSE) -> DTM | B18: DTMPRODUKT | C18: =VLOOKUP($B18,__Ciselnik!$A$1:$H$202,7,FALSE) -> psc.sp98.dtmprodukt25-bc | D18: =VLOOKUP($B18,__Ciselnik!$A$1:$H$202,8,FALSE) -> psc.sp98.dtmprodukt25 | E18: =VLOOKUP($B18,__Ciselnik!$A$1:$I$202,9,FALSE) -> USYC.SP98 | F18: =VLOOKUP($B18,__Ciselnik!$A$1:$C$202,3,FALSE) -> Ostatní | G18: =VLOOKUP($B18,__Ciselnik!$A$1:$D$202,4,FALSE) -> Budinská | H18: =VLOOKUP($B18,__Ciselnik!$A$1:$E$202,5,FALSE) -> 1 | M18: 2 | Q18: 2 | U18: 2 | Z18: 2 | AD18: 1 | AH18: 2 | AM18: 2 | AQ18: 2 | AU18: 2 | AZ18: 2 | BD18: 2 | BJ18: 0 | BK18: =BJ18-SUM(I18:BI18) -> -21 | BL18: =SUM(I18:M18) -> 2 | BM18: =SUM(N18:Q18) -> 2 | BN18: =SUM(R18:U18)+(2/4*V18) -> 2 | BO18: =SUM(W18:Z18)+(2/4*V18) -> 2 | BP18: =SUM(AA18:AD18) -> 1 | BQ18: =SUM(AE18:AH18)+(2/5*AI18) -> 2 | BR18: =SUM(AJ18:AM18)+(3/5*AI18) -> 2 | BS18: =SUM(AN18:AQ18)+(1/5*AR18) -> 2 | BT18: =SUM(AS18:AU18)+(4/5*AR18)+(2/4*AV18) -> 2 | BU18: =SUM(AW18:AZ18)+(2/4*AV18) -> 2 | BV18: =SUM(BA18:BD18)+(1/5*BE18) -> 2 | BW18: =SUM(BF18:BI18)+(4/5*BE18) -> 0 | BX18: =SUM(BL18:BW18) -> 21
A19: =VLOOKUP($B19,__Ciselnik!$A$1:$B$202,2,FALSE) -> MiZE | B19: MZESERVIS26 | C19: =VLOOKUP($B19,__Ciselnik!$A$1:$H$202,7,FALSE) -> psc.sp98.mzeservis25-bc | D19: =VLOOKUP($B19,__Ciselnik!$A$1:$H$202,8,FALSE) -> psc.sp98.mzeservis25 | E19: =VLOOKUP($B19,__Ciselnik!$A$1:$I$202,9,FALSE) -> USYC.SP98 | F19: =VLOOKUP($B19,__Ciselnik!$A$1:$C$202,3,FALSE) -> ESRI | G19: =VLOOKUP($B19,__Ciselnik!$A$1:$D$202,4,FALSE) -> Budinská | H19: =VLOOKUP($B19,__Ciselnik!$A$1:$E$202,5,FALSE) -> 1 | J19: 6 | K19: 10 | L19: 10 | M19: 8 | N19: 10 | O19: 8 | P19: 8 | Q19: 4 | R19: 8 | S19: 8 | T19: 8 | U19: 8 | V19: 8 | W19: 8 | X19: 8 | Y19: 8 | Z19: 8 | AA19: 8 | AB19: 8 | AC19: 8 | AD19: 8 | AE19: 8 | AF19: 8 | AG19: 8 | AH19: 8 | AK19: 8 | AL19: 8 | AM19: 8 | AN19: 8 | AO19: 8 | AP19: 8 | AQ19: 8 | AR19: 8 | AS19: 8 | AT19: 8 | AU19: 8 | AV19: 8 | AW19: 8 | AX19: 8 | AY19: 8 | AZ19: 8 | BA19: 8 | BB19: 8 | BC19: 8 | BD19: 8 | BE19: 8 | BF19: 8 | BG19: 8 | BJ19: 0 | BK19: =BJ19-SUM(I19:BI19) -> -384 | BL19: =SUM(I19:M19) -> 34 | BM19: =SUM(N19:R19) -> 38 | BN19: =SUM(R19:U19)+(2/4*V19) -> 36 | BO19: =SUM(W19:Z19)+(2/4*V19) -> 36 | BP19: =SUM(AA19:AD19) -> 32 | BQ19: =SUM(AE19:AH19)+(2/5*AI19) -> 32 | BR19: =SUM(AJ19:AM19)+(3/5*AI19) -> 24 | BS19: =SUM(AN19:AQ19)+(1/5*AR19) -> 34 | BT19: =SUM(AS19:AU19)+(4/5*AR19)+(2/4*AV19) -> 34 | BU19: =SUM(AW19:AZ19)+(2/4*AV19) -> 36 | BV19: =SUM(BA19:BD19)+(1/5*BE19) -> 34 | BW19: =SUM(BF19:BI19)+(4/5*BE19) -> 22 | BX19: =SUM(BL19:BW19) -> 392
A20: =VLOOKUP($B20,__Ciselnik!$A$1:$B$202,2,FALSE) -> MiZE | B20: MZEROZVOJ26 | C20: =VLOOKUP($B20,__Ciselnik!$A$1:$H$202,7,FALSE) -> psc.sp98.mzerozvoj25-bc | D20: =VLOOKUP($B20,__Ciselnik!$A$1:$H$202,8,FALSE) -> psc.sp98.mzerozvoj25 | E20: =VLOOKUP($B20,__Ciselnik!$A$1:$I$202,9,FALSE) -> USYC.SP98 | F20: =VLOOKUP($B20,__Ciselnik!$A$1:$C$202,3,FALSE) -> ESRI | G20: =VLOOKUP($B20,__Ciselnik!$A$1:$D$202,4,FALSE) -> Budinská | H20: =VLOOKUP($B20,__Ciselnik!$A$1:$E$202,5,FALSE) -> 1 | J20: 0 | K20: 0 | L20: 0 | M20: 0 | BJ20: 0 | BK20: =BJ20-SUM(I20:BI20) -> 0 | BL20: =SUM(I20:M20) -> 0 | BM20: =SUM(N20:Q20) -> 0 | BN20: =SUM(R20:U20)+(2/4*V20) -> 0 | BO20: =SUM(W20:Z20)+(2/4*V20) -> 0 | BP20: =SUM(AA20:AD20) -> 0 | BQ20: =SUM(AE20:AH20)+(2/5*AI20) -> 0 | BR20: =SUM(AJ20:AM20)+(3/5*AI20) -> 0 | BS20: =SUM(AN20:AQ20)+(1/5*AR20) -> 0 | BT20: =SUM(AS20:AU20)+(4/5*AR20)+(2/4*AV20) -> 0 | BU20: =SUM(AW20:AZ20)+(2/4*AV20) -> 0 | BV20: =SUM(BA20:BD20)+(1/5*BE20) -> 0 | BW20: =SUM(BF20:BI20)+(4/5*BE20) -> 0 | BX20: =SUM(BL20:BW20) -> 0
A21: =VLOOKUP($B21,__Ciselnik!$A$1:$B$202,2,FALSE) -> TZ | B21: TZ26 | D21: =VLOOKUP($B21,__Ciselnik!$A$1:$H$202,8,FALSE) -> psc.sp98.tz25 | E21: =VLOOKUP($B21,__Ciselnik!$A$1:$I$202,9,FALSE) -> USYC.SP98 | F21: =VLOOKUP($B21,__Ciselnik!$A$1:$C$202,3,FALSE) -> Esri | G21: =VLOOKUP($B21,__Ciselnik!$A$1:$D$202,4,FALSE) -> Budinská | H21: =VLOOKUP($B21,__Ciselnik!$A$1:$E$202,5,FALSE) -> 1 | J21: 2 | K21: 2 | L21: 2 | M21: 2 | N21: 2 | S21: 2 | T21: 2 | U21: 2 | V21: 2 | W21: 2 | X21: 4 | Y21: 2 | Z21: 2 | AA21: 2 | AB21: 2 | AC21: 2 | AD21: 4 | AE21: 2 | AF21: 2 | AG21: 2 | AH21: 4 | AK21: 2 | AL21: 4 | AM21: 2 | AN21: 2 | AO21: 2 | AP21: 2 | AQ21: 4 | AR21: 2 | AS21: 2 | AT21: 2 | AU21: 4 | AV21: 2 | AW21: 2 | AX21: 2 | AY21: 4 | AZ21: 2 | BA21: 2 | BB21: 2 | BC21: 2 | BD21: 4 | BE21: 2 | BF21: 2 | BG21: 2 | BJ21: 0 | BK21: =BJ21-SUM(I21:BI21) -> -104 | BL21: =SUM(I21:T21) -> 14 | BM21: =SUM(U21:W21) -> 6 | BN21: =SUM(#REF!)+(2/4*#REF!) -> #REF! | BO21: =SUM(X21:Z21)+(2/4*#REF!) -> #REF! | BP21: =SUM(AA21:AD21) -> 10 | BQ21: =SUM(AE21:AH21)+(2/5*AI21) -> 10 | BR21: =SUM(AJ21:AM21)+(3/5*AI21) -> 8 | BS21: =SUM(AN21:AQ21)+(1/5*AR21) -> 10 | BT21: =SUM(AS21:AU21)+(4/5*AR21)+(2/4*AV21) -> 11 | BU21: =SUM(AW21:AZ21)+(2/4*AV21) -> 11 | BV21: =SUM(BA21:BD21)+(1/5*BE21) -> 10 | BW21: =SUM(BF21:BI21)+(4/5*BE21) -> 6 | BX21: =SUM(BL21:BW21) -> #REF!
A22: =VLOOKUP($B22,__Ciselnik!$A$1:$B$202,2,FALSE) -> ST | B22: ST - Výstavba 2026 | C22: =VLOOKUP($B22,__Ciselnik!$A$1:$H$202,7,FALSE) -> psc.st_constr-bc | D22: =VLOOKUP($B22,__Ciselnik!$A$1:$H$202,8,FALSE) -> psc.sp97.st | E22: =VLOOKUP($B22,__Ciselnik!$A$1:$I$202,9,FALSE) -> USYC.SP97 | F22: =VLOOKUP($B22,__Ciselnik!$A$1:$C$202,3,FALSE) -> Ostatní | G22: =VLOOKUP($B22,__Ciselnik!$A$1:$D$202,4,FALSE) -> Budinská | H22: =VLOOKUP($B22,__Ciselnik!$A$1:$E$202,5,FALSE) -> 1 | J22: 8 | K22: 8 | L22: 8 | M22: 8 | N22: 4 | O22: 4 | P22: 8 | Q22: 4 | R22: 4 | S22: 4 | T22: 4 | U22: 4 | V22: 4 | W22: 4 | X22: 4 | Y22: 4 | Z22: 4 | AA22: 4 | AB22: 4 | AC22: 4 | AD22: 4 | AE22: 4 | AF22: 4 | AG22: 4 | AH22: 4 | BJ22: 0 | BK22: =BJ22-SUM(I22:BI22) -> -120 | BL22: =SUM(I22:M22) -> 32 | BM22: =SUM(N22:Q22) -> 20 | BN22: =SUM(R22:U22)+(2/4*V22) -> 18 | BO22: =SUM(W22:Z22)+(2/4*V22) -> 18 | BP22: =SUM(AA22:AD22) -> 16 | BQ22: =SUM(AE22:AH22)+(2/5*AI22) -> 16 | BR22: =SUM(AJ22:AM22)+(3/5*AI22) -> 0 | BS22: =SUM(AN22:AQ22)+(1/5*AR22) -> 0 | BT22: =SUM(AS22:AU22)+(4/5*AR22)+(2/4*AV22) -> 0 | BU22: =SUM(AW22:AZ22)+(2/4*AV22) -> 0 | BV22: =SUM(BA22:BD22)+(1/5*BE22) -> 0 | BW22: =SUM(BF22:BI22)+(4/5*BE22) -> 0 | BX22: =SUM(BL22:BW22) -> 120
A23: =VLOOKUP($B23,__Ciselnik!$A$1:$B$202,2,FALSE) -> PPas | B23: PPas - Výstavba 2.etapa | D23: =VLOOKUP($B23,__Ciselnik!$A$1:$H$202,8,FALSE) -> psc.sp97.ppas25 | E23: =VLOOKUP($B23,__Ciselnik!$A$1:$I$202,9,FALSE) -> USYC.SP97 | F23: =VLOOKUP($B23,__Ciselnik!$A$1:$C$202,3,FALSE) -> Ostatní | G23: =VLOOKUP($B23,__Ciselnik!$A$1:$D$202,4,FALSE) -> Budinská | H23: =VLOOKUP($B23,__Ciselnik!$A$1:$E$202,5,FALSE) -> 1 | P23: 16 | Q23: 16 | R23: 16 | S23: 10 | T23: 10 | U23: 10 | V23: 10 | W23: 10 | X23: 10 | Y23: 10 | Z23: 10 | AA23: 10 | AB23: 10 | AC23: 10 | AD23: 10 | AE23: 10 | AF23: 10 | AG23: 10 | AH23: 10 | AI23: 10 | AJ23: 10 | AK23: 10 | AL23: 10 | AM23: 10 | AN23: 10 | AO23: 10 | AP23: 10 | AQ23: 10 | AR23: 10 | AS23: 10 | AT23: 10 | AU23: 10 | AV23: 10 | AW23: 10 | AX23: 10 | AY23: 10 | AZ23: 10 | BA23: 10 | BB23: 10 | BC23: 10 | BD23: 10 | BE23: 10 | BF23: 10 | BG23: 10 | BH23: 10 | BJ23: 0 | BK23: =BJ23-SUM(I23:BI23) -> -468 | BL23: =SUM(I23:M23) -> 0 | BM23: =SUM(N23:Q23) -> 32 | BN23: =SUM(R23:U23)+(2/4*V23) -> 51 | BO23: =SUM(W23:Z23)+(2/4*V23) -> 45 | BP23: =SUM(AA23:AD23) -> 40 | BQ23: =SUM(AE23:AH23)+(2/5*AI23) -> 44 | BR23: =SUM(AJ23:AM23)+(3/5*AI23) -> 46 | BS23: =SUM(AN23:AQ23)+(1/5*AR23) -> 42 | BT23: =SUM(AS23:AU23)+(4/5*AR23)+(2/4*AV23) -> 43 | BU23: =SUM(AW23:AZ23)+(2/4*AV23) -> 45 | BV23: =SUM(BA23:BD23)+(1/5*BE23) -> 42 | BW23: =SUM(BF23:BI23)+(4/5*BE23) -> 38 | BX23: =SUM(BL23:BW23) -> 468
A24: =VLOOKUP($B24,__Ciselnik!$A$1:$B$202,2,FALSE) -> PPas | B24: PPas Servis 2026 | C24: =VLOOKUP($B24,__Ciselnik!$A$1:$H$202,7,FALSE) -> psc.pp_servis_25-bc | D24: =VLOOKUP($B24,__Ciselnik!$A$1:$H$202,8,FALSE) -> psc.sp97.ppas25 | E24: =VLOOKUP($B24,__Ciselnik!$A$1:$I$202,9,FALSE) -> USYC.SP97 | F24: =VLOOKUP($B24,__Ciselnik!$A$1:$C$202,3,FALSE) -> Ostatní | G24: =VLOOKUP($B24,__Ciselnik!$A$1:$D$202,4,FALSE) -> Budinská | H24: =VLOOKUP($B24,__Ciselnik!$A$1:$E$202,5,FALSE) -> 1 | R24: 2 | S24: 2 | T24: 2 | U24: 2 | V24: 2 | W24: 2 | X24: 2 | Y24: 2 | Z24: 2 | AA24: 2 | AB24: 2 | AC24: 2 | AD24: 2 | AE24: 2 | AF24: 2 | AG24: 2 | AH24: 2 | AI24: 2 | AJ24: 2 | AK24: 2 | AL24: 2 | AM24: 2 | AN24: 2 | AO24: 2 | AP24: 2 | AQ24: 2 | AR24: 2 | AS24: 2 | AT24: 2 | AU24: 2 | AV24: 2 | AW24: 2 | AX24: 2 | AY24: 2 | AZ24: 2 | BA24: 2 | BB24: 2 | BC24: 2 | BD24: 2 | BE24: 2 | BF24: 2 | BG24: 2 | BH24: 2 | BJ24: 0 | BK24: =BJ24-SUM(I24:BI24) -> -86 | BL24: =SUM(I24:M24) -> 0 | BM24: =SUM(N24:Q24) -> 0 | BN24: =SUM(R24:U24)+(2/4*V24) -> 9 | BO24: =SUM(W24:Z24)+(2/4*V24) -> 9 | BP24: =SUM(AA24:AD24) -> 8 | BQ24: =SUM(AE24:AH24)+(2/5*AI24) -> 9 | BR24: =SUM(AJ24:AM24)+(3/5*AI24) -> 9 | BS24: =SUM(AN24:AQ24)+(1/5*AR24) -> 8 | BT24: =SUM(AS24:AU24)+(4/5*AR24)+(2/4*AV24) -> 9 | BU24: =SUM(AW24:AZ24)+(2/4*AV24) -> 9 | BV24: =SUM(BA24:BD24)+(1/5*BE24) -> 8 | BW24: =SUM(BF24:BI24)+(4/5*BE24) -> 8 | BX24: =SUM(BL24:BW24) -> 86

Sheet Faflík
A1: =RIGHT(CELL("názevsouboru"),LEN(CELL("názevsouboru"))-FIND("]",CELL("názevsouboru"))) -> Faflík | B1: DEV FE | I1: =__Ciselnik!L2 -> 45292 | N1: =EDATE(I1,1) -> 45323 | R1: =EDATE(N1,1) -> 45352 | V1: =EDATE(R1,1) -> 45383 | AA1: =EDATE(V1,1) -> 45413 | AE1: =EDATE(AA1,1) -> 45444 | AI1: =EDATE(AE1,1) -> 45474 | AN1: =EDATE(AI1,1) -> 45505 | AR1: =EDATE(AN1,1) -> 45536 | AV1: =EDATE(AR1,1) -> 45566 | BA1: =EDATE(AV1,1) -> 45597 | BE1: =EDATE(BA1,1) -> 45627 | BL1: Plánované hodiny celkem
A2: Kurátor: | B2: DD | G2: Týden | I2: 1 | J2: 2 | K2: 3 | L2: 4 | M2: 5 | N2: 6 | O2: 7 | P2: 8 | Q2: 9 | R2: 10 | S2: 11 | T2: 12 | U2: 13 | V2: 14 | W2: 15 | X2: 16 | Y2: 17 | Z2: 18 | AA2: 19 | AB2: 20 | AC2: 21 | AD2: 22 | AE2: 23 | AF2: 24 | AG2: 25 | AH2: 26 | AI2: 27 | AJ2: 28 | AK2: 29 | AL2: 30 | AM2: 31 | AN2: 32 | AO2: 33 | AP2: 34 | AQ2: 35 | AR2: 36 | AS2: 37 | AT2: 38 | AU2: 39 | AV2: 40 | AW2: 41 | AX2: 42 | AY2: 43 | AZ2: 44 | BA2: 45 | BB2: 46 | BC2: 47 | BD2: 48 | BE2: 49 | BF2: 50 | BG2: 51 | BH2: 52 | BI2: 53 | BL2: =__Ciselnik!L2 -> 45292 | BM2: =EDATE(BL2,1) -> 45323 | BN2: =EDATE(BM2,1) -> 45352 | BO2: =EDATE(BN2,1) -> 45383 | BP2: =EDATE(BO2,1) -> 45413 | BQ2: =EDATE(BP2,1) -> 45444 | BR2: =EDATE(BQ2,1) -> 45474 | BS2: =EDATE(BR2,1) -> 45505 | BT2: =EDATE(BS2,1) -> 45536 | ... BW2: =EDATE(BV2,1) -> 45627 | BX2: 2026
A3: Jednotka: | B3: telco | G3: Kapacita | I3: 8 | J3: 40 | K3: 40 | L3: 40 | M3: 40 | N3: 40 | O3: 40 | P3: 40 | Q3: 40 | R3: 40 | S3: 40 | T3: 40 | U3: 40 | V3: 32 | W3: 32 | X3: 40 | Y3: 40 | Z3: 32 | AA3: 32 | AB3: 40 | AC3: 40 | AD3: 40 | AE3: 40 | AF3: 40 | AG3: 40 | AH3: 40 | AI3: 40 | AJ3: 32 | AK3: 40 | AL3: 40 | AM3: 40 | AN3: 40 | AO3: 40 | AP3: 40 | AQ3: 40 | AR3: 40 | AS3: 40 | AT3: 40 | AU3: 40 | AV3: 32 | AW3: 40 | AX3: 40 | AY3: 40 | AZ3: 32 | BA3: 40 | BB3: 40 | BC3: 32 | BD3: 40 | BE3: 40 | BF3: 40 | BG3: 40 | BH3: 24 | BI3: 32 | BL3: =SUM(I3:M3) -> 168 | BM3: =SUM(N3:Q3) -> 160 | BN3: =SUM(R3:U3)+(2/4*V3) -> 176 | BO3: =SUM(W3:Z3)+(2/4*V3) -> 160 | BP3: =SUM(AA3:AD3) -> 152 | BQ3: =SUM(AE3:AH3)+(2/5*AI3) -> 176 | BR3: =SUM(AJ3:AM3)+(3/5*AI3) -> 176 | BS3: =SUM(AN3:AQ3)+(1/5*AR3) -> 168 | BT3: =SUM(AS3:AU3)+(4/5*AR3)+(2/4*AV3) -> 168 | BU3: =SUM(AW3:AZ3)+(2/4*AV3) -> 168 | BV3: =SUM(BA3:BD3)+(1/5*BE3) -> 160 | BW3: =SUM(BF3:BI3)+(4/5*BE3) -> 168 | BX3: =SUM(BL3:BW3) -> 2000
A4: Generovat | B4: Ano | G4: Volná kapacita | I4: =I3-I5 -> #N/A | J4: =J3-J5 -> #N/A | K4: =K3-K5 -> #N/A | L4: =L3-L5 -> #N/A | M4: =M3-M5 -> #N/A | N4: =N3-N5 -> #N/A | O4: =O3-O5 -> #N/A | P4: =P3-P5 -> #N/A | ... BI4: =BI3-BI5 -> #N/A | BL4: =BL3-BL5 -> 20 | BM4: =BM3-BM5 -> 10 | BN4: =BN3-BN5 -> -8 | BO4: =BO3-BO5 -> 14 | BP4: =BP3-BP5 -> 30 | BQ4: =BQ3-BQ5 -> 42 | BR4: =BR3-BR5 -> 26 | BS4: =BS3-BS5 -> 48 | ... BW4: =BW3-BW5 -> 30 | BX4: =SUM(BL4:BW4) -> 332
G5: Celkové vytížení | I5: =SUMPRODUCT(I10:I37,$H$10:$H$37) -> #N/A | J5: =SUMPRODUCT(J10:J37,$H$10:$H$37) -> #N/A | K5: =SUMPRODUCT(K10:K37,$H$10:$H$37) -> #N/A | L5: =SUMPRODUCT(L10:L37,$H$10:$H$37) -> #N/A | M5: =SUMPRODUCT(M10:M37,$H$10:$H$37) -> #N/A | N5: =SUMPRODUCT(N10:N37,$H$10:$H$37) -> #N/A | O5: =SUMPRODUCT(O10:O37,$H$10:$H$37) -> #N/A | P5: =SUMPRODUCT(P10:P37,$H$10:$H$37) -> #N/A | ... BI5: =SUMPRODUCT(BI10:BI37,$H$10:$H$37) -> #N/A | BL5: =SUM(BL10:BL37) -> 148 | BM5: =SUM(BM10:BM37) -> 150 | BN5: =SUM(BN10:BN37) -> 184 | BO5: =SUM(BO10:BO37) -> 146 | BP5: =SUM(BP10:BP37) -> 122 | BQ5: =SUM(BQ10:BQ37) -> 134 | BR5: =SUM(BR10:BR37) -> 150 | BS5: =SUM(BS10:BS37) -> 120 | ... BX5: =SUM(BX10:BX37) -> 1668
G6: V rámci SP97 | I6: {=SUMPRODUCT(I10:I37,$H$10:$H$37*($E$10:$E$37="USYC.SP97"))} -> #N/A | J6: {=SUMPRODUCT(J10:J37,$H$10:$H$37*($E$10:$E$37="USYC.SP97"))} -> #N/A | K6: {=SUMPRODUCT(K10:K37,$H$10:$H$37*($E$10:$E$37="USYC.SP97"))} -> #N/A | L6: {=SUMPRODUCT(L10:L37,$H$10:$H$37*($E$10:$E$37="USYC.SP97"))} -> #N/A | M6: {=SUMPRODUCT(M10:M37,$H$10:$H$37*($E$10:$E$37="USYC.SP97"))} -> #N/A | N6: {=SUMPRODUCT(N10:N37,$H$10:$H$37*($E$10:$E$37="USYC.SP97"))} -> #N/A | O6: {=SUMPRODUCT(O10:O37,$H$10:$H$37*($E$10:$E$37="USYC.SP97"))} -> #N/A | P6: {=SUMPRODUCT(P10:P37,$H$10:$H$37*($E$10:$E$37="USYC.SP97"))} -> #N/A | ... BI6: {=SUMPRODUCT(BI10:BI37,$H$10:$H$37*($E$10:$E$37="USYC.SP97"))} -> #N/A | BL6: =SUMIF($E$10:$E$37,"USYC.SP97",BL10:BL37) -> 120 | BM6: =SUMIF($E$10:$E$37,"USYC.SP97",BM10:BM37) -> 102 | BN6: =SUMIF($E$10:$E$37,"USYC.SP97",BN10:BN37) -> 84 | BO6: =SUMIF($E$10:$E$37,"USYC.SP97",BO10:BO37) -> 48 | BP6: =SUMIF($E$10:$E$37,"USYC.SP97",BP10:BP37) -> 30 | BQ6: =SUMIF($E$10:$E$37,"USYC.SP97",BQ10:BQ37) -> 20 | BR6: =SUMIF($E$10:$E$37,"USYC.SP97",BR10:BR37) -> 16 | BS6: =SUMIF($E$10:$E$37,"USYC.SP97",BS10:BS37) -> 20 | ... BX6: =SUMIF($E$10:$E$37,"USYC.SP97",BX10:BX37) -> 514
G7: V rámci SP98 | I7: {=SUMPRODUCT(I10:I37,$H$10:$H$37*($E$10:$E$37="USYC.SP98"))} -> #N/A | J7: {=SUMPRODUCT(J10:J37,$H$10:$H$37*($E$10:$E$37="USYC.SP98"))} -> #N/A | K7: {=SUMPRODUCT(K10:K37,$H$10:$H$37*($E$10:$E$37="USYC.SP98"))} -> #N/A | L7: {=SUMPRODUCT(L10:L37,$H$10:$H$37*($E$10:$E$37="USYC.SP98"))} -> #N/A | M7: {=SUMPRODUCT(M10:M37,$H$10:$H$37*($E$10:$E$37="USYC.SP98"))} -> #N/A | N7: {=SUMPRODUCT(N10:N37,$H$10:$H$37*($E$10:$E$37="USYC.SP98"))} -> #N/A | O7: {=SUMPRODUCT(O10:O37,$H$10:$H$37*($E$10:$E$37="USYC.SP98"))} -> #N/A | P7: {=SUMPRODUCT(P10:P37,$H$10:$H$37*($E$10:$E$37="USYC.SP98"))} -> #N/A | ... BI7: {=SUMPRODUCT(BI10:BI37,$H$10:$H$37*($E$10:$E$37="USYC.SP98"))} -> #N/A | BL7: =SUMIF($E$10:$E$37,"USYC.SP98",BL10:BL37) -> 0 | BM7: =SUMIF($E$10:$E$37,"USYC.SP98",BM10:BM37) -> 0 | BN7: =SUMIF($E$10:$E$37,"USYC.SP98",BN10:BN37) -> 5 | BO7: =SUMIF($E$10:$E$37,"USYC.SP98",BO10:BO37) -> 9 | BP7: =SUMIF($E$10:$E$37,"USYC.SP98",BP10:BP37) -> 8 | BQ7: =SUMIF($E$10:$E$37,"USYC.SP98",BQ10:BQ37) -> 9 | BR7: =SUMIF($E$10:$E$37,"USYC.SP98",BR10:BR37) -> 9 | BS7: =SUMIF($E$10:$E$37,"USYC.SP98",BS10:BS37) -> 8 | ... BX7: =SUMIF($E$10:$E$37,"USYC.SP98",BX10:BX37) -> 80
G8: Externě | I8: {=SUMPRODUCT(I10:I37,$H$10:$H$37*($E$10:$E$37="Ext"))} -> #N/A | J8: {=SUMPRODUCT(J10:J37,$H$10:$H$37*($E$10:$E$37="Ext"))} -> #N/A | K8: {=SUMPRODUCT(K10:K37,$H$10:$H$37*($E$10:$E$37="Ext"))} -> #N/A | L8: {=SUMPRODUCT(L10:L37,$H$10:$H$37*($E$10:$E$37="Ext"))} -> #N/A | M8: {=SUMPRODUCT(M10:M37,$H$10:$H$37*($E$10:$E$37="Ext"))} -> #N/A | N8: {=SUMPRODUCT(N10:N37,$H$10:$H$37*($E$10:$E$37="Ext"))} -> #N/A | O8: {=SUMPRODUCT(O10:O37,$H$10:$H$37*($E$10:$E$37="Ext"))} -> #N/A | P8: {=SUMPRODUCT(P10:P37,$H$10:$H$37*($E$10:$E$37="Ext"))} -> #N/A | ... BI8: {=SUMPRODUCT(BI10:BI37,$H$10:$H$37*($E$10:$E$37="Ext"))} -> #N/A | BL8: =SUMIF($E$10:$E$37,"Ext",BL10:BL37) -> 20 | BM8: =SUMIF($E$10:$E$37,"Ext",BM10:BM37) -> 40 | BN8: =SUMIF($E$10:$E$37,"Ext",BN10:BN37) -> 88 | BO8: =SUMIF($E$10:$E$37,"Ext",BO10:BO37) -> 80 | BP8: =SUMIF($E$10:$E$37,"Ext",BP10:BP37) -> 76 | BQ8: =SUMIF($E$10:$E$37,"Ext",BQ10:BQ37) -> 96 | BR8: =SUMIF($E$10:$E$37,"Ext",BR10:BR37) -> 116 | BS8: =SUMIF($E$10:$E$37,"Ext",BS10:BS37) -> 84 | ... BX8: =SUMIF($E$10:$E$37,"Ext",BX10:BX37) -> 980
A9: Klient | B9: Projekt | C9: BC | D9: Deal Unit | E9: Jednotka | F9: Oblast | G9: PM | H9: Koef. | I9: - | J9: - | K9: - | L9: - | M9: - | N9: - | O9: - | P9: - | Q9: - | R9: - | S9: - | T9: - | U9: - | V9: - | W9: - | X9: - | Y9: - | Z9: - | AA9: - | AB9: - | AC9: - | AD9: - | AE9: - | AF9: - | AG9: - | AH9: - | AI9: - | AJ9: - | AK9: - | AL9: - | AM9: - | AN9: - | AO9: - | AP9: - | AQ9: - | AR9: - | AS9: - | AT9: - | AU9: - | AV9: - | AW9: - | AX9: - | AY9: - | AZ9: - | BA9: - | BB9: - | BC9: - | BD9: - | BE9: - | BF9: - | BG9: - | BH9: - | BI9: - | BJ9: Plán | BK9: Zbývá
A10: =VLOOKUP($B10,__Ciselnik!$A$1:$B$202,2,FALSE) -> - | B10: =__Ciselnik!A2 -> _aktivity mimo Geo | C10: =VLOOKUP($B10,__Ciselnik!$A$1:$H$202,7,FALSE) -> - | D10: =VLOOKUP($B10,__Ciselnik!$A$1:$H$202,8,FALSE) -> - | E10: =VLOOKUP($B10,__Ciselnik!$A$1:$I$202,9,FALSE) -> Ext | F10: =VLOOKUP($B10,__Ciselnik!$A$1:$C$202,3,FALSE) -> - | G10: =VLOOKUP($B10,__Ciselnik!$A$1:$D$202,4,FALSE) -> - | H10: =VLOOKUP($B10,__Ciselnik!$A$1:$E$202,5,FALSE) -> 1 | R10: 20 | S10: 20 | T10: 20 | U10: 20 | V10: 16 | W10: 16 | X10: 20 | Y10: 20 | Z10: 16 | AA10: 16 | AB10: 20 | AC10: 20 | AD10: 20 | AE10: 20 | AF10: 20 | AG10: 20 | AH10: 20 | AK10: 20 | AL10: 20 | AM10: 20 | AN10: 20 | AO10: 20 | AP10: 20 | AQ10: 20 | AR10: 20 | AS10: 20 | AT10: 20 | AU10: 20 | AV10: 16 | AW10: 20 | AX10: 20 | AY10: 20 | AZ10: 12 | BA10: 20 | BB10: 20 | BC10: 16 | BD10: 20 | BE10: 20 | BF10: 20 | BG10: 20 | BK10: =BJ10-SUM(I10:BI10) -> -768 | BL10: =SUM(I10:M10) -> 0 | BM10: =SUM(N10:Q10) -> 0 | BN10: =SUM(R10:U10)+(2/4*V10) -> 88 | BO10: =SUM(W10:Z10)+(2/4*V10) -> 80 | BP10: =SUM(AA10:AD10) -> 76 | BQ10: =SUM(AE10:AH10)+(2/5*AI10) -> 80 | BR10: =SUM(AJ10:AM10)+(3/5*AI10) -> 60 | BS10: =SUM(AN10:AQ10)+(1/5*AR10) -> 84 | BT10: =SUM(AS10:AU10)+(4/5*AR10)+(2/4*AV10) -> 84 | BU10: =SUM(AW10:AZ10)+(2/4*AV10) -> 80 | BV10: =SUM(BA10:BD10)+(1/5*BE10) -> 80 | BW10: =SUM(BF10:BI10)+(4/5*BE10) -> 56 | BX10: =SUM(BL10:BW10) -> 768
A11: =VLOOKUP($B11,__Ciselnik!$A$1:$B$202,2,FALSE) -> - | B11: =__Ciselnik!A3 -> _dovolená/nemoc | C11: =VLOOKUP($B11,__Ciselnik!$A$1:$H$202,7,FALSE) -> - | D11: =VLOOKUP($B11,__Ciselnik!$A$1:$H$202,8,FALSE) -> - | E11: =VLOOKUP($B11,__Ciselnik!$A$1:$I$202,9,FALSE) -> Ext | F11: =VLOOKUP($B11,__Ciselnik!$A$1:$C$202,3,FALSE) -> - | G11: =VLOOKUP($B11,__Ciselnik!$A$1:$D$202,4,FALSE) -> - | H11: =VLOOKUP($B11,__Ciselnik!$A$1:$E$202,5,FALSE) -> 1 | I11: 8 | M11: 12 | N11: 40 | AI11: 40 | AJ11: 32 | AZ11: 16 | BC11: 8 | BH11: 24 | BI11: 32 | BJ11: 200 | BK11: =BJ11-SUM(I11:BI11) -> -12 | BL11: =SUM(I11:M11) -> 20 | BM11: =SUM(N11:Q11) -> 40 | BN11: =SUM(R11:U11)+(2/4*V11) -> 0 | BO11: =SUM(W11:Z11)+(2/4*V11) -> 0 | BP11: =SUM(AA11:AD11) -> 0 | BQ11: =SUM(AE11:AH11)+(2/5*AI11) -> 16 | BR11: =SUM(AJ11:AM11)+(3/5*AI11) -> 56 | BS11: =SUM(AN11:AQ11)+(1/5*AR11) -> 0 | BT11: =SUM(AS11:AU11)+(4/5*AR11)+(2/4*AV11) -> 0 | BU11: =SUM(AW11:AZ11)+(2/4*AV11) -> 16 | BV11: =SUM(BA11:BD11)+(1/5*BE11) -> 8 | BW11: =SUM(BF11:BI11)+(4/5*BE11) -> 56 | BX11: =SUM(BL11:BW11) -> 212
A12: =VLOOKUP($B12,__Ciselnik!$A$1:$B$202,2,FALSE) -> - | B12: _presale 97 | C12: =VLOOKUP($B12,__Ciselnik!$A$1:$H$202,7,FALSE) -> psc.sp97 | D12: =VLOOKUP($B12,__Ciselnik!$A$1:$H$202,8,FALSE) -> - | E12: =VLOOKUP($B12,__Ciselnik!$A$1:$I$202,9,FALSE) -> USYC.SP97 | F12: =VLOOKUP($B12,__Ciselnik!$A$1:$C$202,3,FALSE) -> - | G12: =VLOOKUP($B12,__Ciselnik!$A$1:$D$202,4,FALSE) -> - | H12: =VLOOKUP($B12,__Ciselnik!$A$1:$E$202,5,FALSE) -> 1 | S12: 16 | BK12: =BJ12-SUM(I12:BI12) -> -16 | BL12: =SUM(I12:M12) -> 0 | BM12: =SUM(N12:Q12) -> 0 | BN12: =SUM(R12:U12)+(2/4*V12) -> 16 | BO12: =SUM(W12:Z12)+(2/4*V12) -> 0 | BP12: =SUM(AA12:AD12) -> 0 | BQ12: =SUM(AE12:AH12)+(2/5*AI12) -> 0 | BR12: =SUM(AJ12:AM12)+(3/5*AI12) -> 0 | BS12: =SUM(AN12:AQ12)+(1/5*AR12) -> 0 | BT12: =SUM(AS12:AU12)+(4/5*AR12)+(2/4*AV12) -> 0 | BU12: =SUM(AW12:AZ12)+(2/4*AV12) -> 0 | BV12: =SUM(BA12:BD12)+(1/5*BE12) -> 0 | BW12: =SUM(BF12:BI12)+(4/5*BE12) -> 0 | BX12: =SUM(BL12:BW12) -> 16
A13: =VLOOKUP($B13,__Ciselnik!$A$1:$B$202,2,FALSE) -> - | B13: =__Ciselnik!A7 -> _režie | C13: =VLOOKUP($B13,__Ciselnik!$A$1:$H$202,7,FALSE) -> - | D13: =VLOOKUP($B13,__Ciselnik!$A$1:$H$202,8,FALSE) -> - | E13: =VLOOKUP($B13,__Ciselnik!$A$1:$I$202,9,FALSE) -> Ext | F13: =VLOOKUP($B13,__Ciselnik!$A$1:$C$202,3,FALSE) -> - | G13: =VLOOKUP($B13,__Ciselnik!$A$1:$D$202,4,FALSE) -> - | H13: =VLOOKUP($B13,__Ciselnik!$A$1:$E$202,5,FALSE) -> 1 | BK13: =BJ13-SUM(I13:BI13) -> 0 | BL13: =SUM(I13:M13) -> 0 | BM13: =SUM(N13:Q13) -> 0 | BN13: =SUM(R13:U13)+(2/4*V13) -> 0 | BO13: =SUM(W13:Z13)+(2/4*V13) -> 0 | BP13: =SUM(AA13:AD13) -> 0 | BQ13: =SUM(AE13:AH13)+(2/5*AI13) -> 0 | BR13: =SUM(AJ13:AM13)+(3/5*AI13) -> 0 | BS13: =SUM(AN13:AQ13)+(1/5*AR13) -> 0 | BT13: =SUM(AS13:AU13)+(4/5*AR13)+(2/4*AV13) -> 0 | BU13: =SUM(AW13:AZ13)+(2/4*AV13) -> 0 | BV13: =SUM(BA13:BD13)+(1/5*BE13) -> 0 | BW13: =SUM(BF13:BI13)+(4/5*BE13) -> 0 | BX13: =SUM(BL13:BW13) -> 0
A14: =VLOOKUP($B14,__Ciselnik!$A$1:$B$202,2,FALSE) -> #N/A | B14: EAD97 vzdělávání | C14: =VLOOKUP($B14,__Ciselnik!$A$1:$H$202,7,FALSE) -> #N/A | D14: =VLOOKUP($B14,__Ciselnik!$A$1:$H$202,8,FALSE) -> #N/A | E14: =VLOOKUP($B14,__Ciselnik!$A$1:$I$202,9,FALSE) -> #N/A | F14: =VLOOKUP($B14,__Ciselnik!$A$1:$C$202,3,FALSE) -> #N/A | G14: =VLOOKUP($B14,__Ciselnik!$A$1:$D$202,4,FALSE) -> #N/A | H14: =VLOOKUP($B14,__Ciselnik!$A$1:$E$202,5,FALSE) -> #N/A | J14: 2 | K14: 2 | L14: 2 | M14: 2 | N14: 2 | O14: 2 | P14: 2 | Q14: 2 | S14: 2 | T14: 2 | U14: 2 | V14: 2 | W14: 2 | X14: 2 | Y14: 2 | Z14: 2 | AA14: 2 | AB14: 2 | AC14: 2 | AD14: 2 | AE14: 2 | AF14: 2 | AG14: 2 | AH14: 2 | AI14: 2 | AJ14: 2 | AK14: 2 | AL14: 2 | AM14: 2 | AN14: 2 | AO14: 2 | AP14: 2 | AQ14: 2 | AR14: 2 | AS14: 2 | AT14: 2 | AU14: 2 | AV14: 2 | AW14: 2 | AX14: 2 | AY14: 2 | BA14: 2 | BB14: 2 | BD14: 2 | BE14: 2 | BF14: 2 | BG14: 2 | BJ14: 0 | BK14: =BJ14-SUM(I14:BI14) -> -94 | BL14: =SUM(I14:M14) -> 8 | BM14: =SUM(N14:Q14) -> 8 | BN14: =SUM(R14:U14)+(2/4*V14) -> 7 | BO14: =SUM(W14:Z14)+(2/4*V14) -> 9 | BP14: =SUM(AA14:AD14) -> 8 | BQ14: =SUM(AE14:AH14)+(2/5*AI14) -> 9 | BR14: =SUM(AJ14:AM14)+(3/5*AI14) -> 9 | BS14: =SUM(AN14:AQ14)+(1/5*AR14) -> 8 | BT14: =SUM(AS14:AU14)+(4/5*AR14)+(2/4*AV14) -> 9 | BU14: =SUM(AW14:AZ14)+(2/4*AV14) -> 7 | BV14: =SUM(BA14:BD14)+(1/5*BE14) -> 6 | BW14: =SUM(BF14:BI14)+(4/5*BE14) -> 6 | BX14: =SUM(BL14:BW14) -> 94
